Workbook
Name Slicer_instant: #N/A
Name Slicer_season: #N/A
Name Slicer_weathersit: #N/A
Name Slicer_weekday: #N/A

Sheet User Demand by Hour
A3: hr | B3: Sum of instant
A4: 0 | B4: 7690
A5: 1 | B5: 7716
A6: 2 | B6: 7164
A7: 3 | B7: 5251
A8: 4 | B8: 5298
A9: 5 | B9: 7287
A10: 6 | B10: 7826
A11: 7 | B11: 7852
A12: 8 | B12: 7878
A13: 9 | B13: 7904
A14: 10 | B14: 7930
A15: 11 | B15: 7956
... A27: 23 | B27: 8060
A28: Grand Total | B28: 186355

Sheet Demand by Weather Condition
A3: weathersit | B3: Sum of instant
A4: 1 | B4: 105251
A5: 2 | B5: 62670
A6: 3 | B6: 17848
A7: 4 | B7: 586
A8: Grand Total | B8: 186355

Sheet Sheet3

Sheet Weekend vs Weekday Demand
A3: DayType | B3: Sum of instant
A4: weekend | B4: 186355
A5: Grand Total | B5: 186355

Sheet dataset_1
A1: instant | B1: dteday | C1: season | D1: yr | E1: mnth | F1: hr | G1: holiday | H1: weekday | I1: weathersit | J1: temp | K1: DayType | L1: SeasonName | M1: Total temp | N1: Avg Temp | O1: Weekend Count | P1: Temp in text | Q1: Left Text | R1: Right Text | S1: Text lenght | T1: Column1 | U1: countif | V1: sumif | W1: StdV | X1: Correl
A2: 1 | B2: 40544 | C2: 1 | D2: 0 | E2: 1 | F2: 0 | G2: FALSE | H2: 6 | I2: 1 | J2: 0.24 | K2: =IF(H2=0,"weekend",IF(H2=6,"weekend","weekend")) -> weekend | L2: =IF(C2=1,"Spring",IF(C2=2,"Summer",IF(C2=3,"Fall","Winter"))) -> Spring | M2: =SUM(J2:J26) -> 8.72 | N2: =AVERAGE(J2:J611) -> 0.19688525 | O2: =COUNT(J2:J611) -> 610 | P2: =TEXT(J2,"0.00") -> 0.24 | Q2: =LEFT(L2,3) -> Spr | R2: =RIGHT(L2,3) -> ing | S2: =LEN(L2) -> 6 | T2: =A2&"|"&B2&"|"&F2 -> 1|40544|0 | U2: =COUNTIF(K:K,"weekend") -> 610 | V2: =SUMIF($K:$K,"weekend",$J:$J) -> 120.1 | W2: =STDEV($J:$J) -> 0.081303845 | X2: =CORREL(J:J,F:F) -> 0.16514795
A3: 2 | B3: 40544 | C3: 1 | D3: 0 | E3: 1 | F3: 1 | G3: FALSE | H3: 6 | I3: 1 | J3: 0.22 | K3: =IF(H3=0,"weekend",IF(H3=6,"weekend","weekend")) -> weekend | L3: =IF(C3=1,"Spring",IF(C3=2,"Summer",IF(C3=3,"Fall","Winter"))) -> Spring | M3: =SUM(J3:J27) -> 8.92 | N3: =AVERAGE(J3:J612) -> 0.19681445 | O3: =COUNT(J3:J612) -> 609 | P3: =TEXT(J3,"0.00") -> 0.22 | Q3: =LEFT(L3,3) -> Spr | R3: =RIGHT(L3,3) -> ing | S3: =LEN(L3) -> 6 | T3: =A3&"|"&B3&"|"&F3 -> 2|40544|1 | U3: =COUNTIF(K:K,"weekend") -> 610 | V3: =SUMIF($K:$K,"weekend",$J:$J) -> 120.1 | W3: =STDEV($J:$J) -> 0.081303845 | X3: =CORREL(J:J,F:F) -> 0.16514795
A4: 3 | B4: 40544 | C4: 1 | D4: 0 | E4: 1 | F4: 2 | G4: FALSE | H4: 6 | I4: 1 | J4: 0.22 | K4: =IF(H4=0,"weekend",IF(H4=6,"weekend","weekend")) -> weekend | L4: =IF(C4=1,"Spring",IF(C4=2,"Summer",IF(C4=3,"Fall","Winter"))) -> Spring | M4: =SUM(J4:J28) -> 9.12 | N4: =AVERAGE(J4:J613) -> 0.19677632 | O4: =COUNT(J4:J613) -> 608 | P4: =TEXT(J4,"0.00") -> 0.22 | Q4: =LEFT(L4,3) -> Spr | R4: =RIGHT(L4,3) -> ing | S4: =LEN(L4) -> 6 | T4: =A4&"|"&B4&"|"&F4 -> 3|40544|2 | U4: =COUNTIF(K:K,"weekend") -> 610 | V4: =SUMIF($K:$K,"weekend",$J:$J) -> 120.1 | W4: =STDEV($J:$J) -> 0.081303845 | X4: =CORREL(J:J,F:F) -> 0.16514795
A5: 4 | B5: 40544 | C5: 1 | D5: 0 | E5: 1 | F5: 3 | G5: FALSE | H5: 6 | I5: 1 | J5: 0.24 | K5: =IF(H5=0,"weekend",IF(H5=6,"weekend","weekend")) -> weekend | L5: =IF(C5=1,"Spring",IF(C5=2,"Summer",IF(C5=3,"Fall","Winter"))) -> Spring | M5: =SUM(J5:J29) -> 9.36 | N5: =AVERAGE(J5:J614) -> 0.19673806 | O5: =COUNT(J5:J614) -> 607 | P5: =TEXT(J5,"0.00") -> 0.24 | Q5: =LEFT(L5,3) -> Spr | R5: =RIGHT(L5,3) -> ing | S5: =LEN(L5) -> 6 | T5: =A5&"|"&B5&"|"&F5 -> 4|40544|3 | U5: =COUNTIF(K:K,"weekend") -> 610 | V5: =SUMIF($K:$K,"weekend",$J:$J) -> 120.1 | W5: =STDEV($J:$J) -> 0.081303845 | X5: =CORREL(J:J,F:F) -> 0.16514795
A6: 5 | B6: 40544 | C6: 1 | D6: 0 | E6: 1 | F6: 4 | G6: FALSE | H6: 6 | I6: 1 | J6: 0.24 | K6: =IF(H6=0,"weekend",IF(H6=6,"weekend","weekend")) -> weekend | L6: =IF(C6=1,"Spring",IF(C6=2,"Summer",IF(C6=3,"Fall","Winter"))) -> Spring | M6: =SUM(J6:J30) -> 9.58 | N6: =AVERAGE(J6:J615) -> 0.19666667 | O6: =COUNT(J6:J615) -> 606 | P6: =TEXT(J6,"0.00") -> 0.24 | Q6: =LEFT(L6,3) -> Spr | R6: =RIGHT(L6,3) -> ing | S6: =LEN(L6) -> 6 | T6: =A6&"|"&B6&"|"&F6 -> 5|40544|4 | U6: =COUNTIF(K:K,"weekend") -> 610 | V6: =SUMIF($K:$K,"weekend",$J:$J) -> 120.1 | W6: =STDEV($J:$J) -> 0.081303845 | X6: =CORREL(J:J,F:F) -> 0.16514795
A7: 6 | B7: 40544 | C7: 1 | D7: 0 | E7: 1 | F7: 5 | G7: FALSE | H7: 6 | I7: 2 | J7: 0.24 | K7: =IF(H7=0,"weekend",IF(H7=6,"weekend","weekend")) -> weekend | L7: =IF(C7=1,"Spring",IF(C7=2,"Summer",IF(C7=3,"Fall","Winter"))) -> Spring | M7: =SUM(J7:J31) -> 9.76 | N7: =AVERAGE(J7:J616) -> 0.19659504 | O7: =COUNT(J7:J616) -> 605 | P7: =TEXT(J7,"0.00") -> 0.24 | Q7: =LEFT(L7,3) -> Spr | R7: =RIGHT(L7,3) -> ing | S7: =LEN(L7) -> 6 | T7: =A7&"|"&B7&"|"&F7 -> 6|40544|5 | U7: =COUNTIF(K:K,"weekend") -> 610 | V7: =SUMIF($K:$K,"weekend",$J:$J) -> 120.1 | W7: =STDEV($J:$J) -> 0.081303845 | X7: =CORREL(J:J,F:F) -> 0.16514795
A8: 7 | B8: 40544 | C8: 1 | D8: 0 | E8: 1 | F8: 6 | G8: FALSE | H8: 6 | I8: 1 | J8: 0.22 | K8: =IF(H8=0,"weekend",IF(H8=6,"weekend","weekend")) -> weekend | L8: =IF(C8=1,"Spring",IF(C8=2,"Summer",IF(C8=3,"Fall","Winter"))) -> Spring | M8: =SUM(J8:J32) -> 9.92 | N8: =AVERAGE(J8:J617) -> 0.19652318 | O8: =COUNT(J8:J617) -> 604 | P8: =TEXT(J8,"0.00") -> 0.22 | Q8: =LEFT(L8,3) -> Spr | R8: =RIGHT(L8,3) -> ing | S8: =LEN(L8) -> 6 | T8: =A8&"|"&B8&"|"&F8 -> 7|40544|6 | U8: =COUNTIF(K:K,"weekend") -> 610 | V8: =SUMIF($K:$K,"weekend",$J:$J) -> 120.1 | W8: =STDEV($J:$J) -> 0.081303845 | X8: =CORREL(J:J,F:F) -> 0.16514795
A9: 8 | B9: 40544 | C9: 1 | D9: 0 | E9: 1 | F9: 7 | G9: FALSE | H9: 6 | I9: 1 | J9: 0.2 | K9: =IF(H9=0,"weekend",IF(H9=6,"weekend","weekend")) -> weekend | L9: =IF(C9=1,"Spring",IF(C9=2,"Summer",IF(C9=3,"Fall","Winter"))) -> Spring | M9: =SUM(J9:J33) -> 10.1 | N9: =AVERAGE(J9:J618) -> 0.19648425 | O9: =COUNT(J9:J618) -> 603 | P9: =TEXT(J9,"0.00") -> 0.20 | Q9: =LEFT(L9,3) -> Spr | R9: =RIGHT(L9,3) -> ing | S9: =LEN(L9) -> 6 | T9: =A9&"|"&B9&"|"&F9 -> 8|40544|7 | U9: =COUNTIF(K:K,"weekend") -> 610 | V9: =SUMIF($K:$K,"weekend",$J:$J) -> 120.1 | W9: =STDEV($J:$J) -> 0.081303845 | X9: =CORREL(J:J,F:F) -> 0.16514795
A10: 9 | B10: 40544 | C10: 1 | D10: 0 | E10: 1 | F10: 8 | G10: FALSE | H10: 6 | I10: 1 | J10: 0.24 | K10: =IF(H10=0,"weekend",IF(H10=6,"weekend","weekend")) -> weekend | L10: =IF(C10=1,"Spring",IF(C10=2,"Summer",IF(C10=3,"Fall","Winter"))) -> Spring | M10: =SUM(J10:J34) -> 10.28 | N10: =AVERAGE(J10:J619) -> 0.19647841 | O10: =COUNT(J10:J619) -> 602 | P10: =TEXT(J10,"0.00") -> 0.24 | Q10: =LEFT(L10,3) -> Spr | R10: =RIGHT(L10,3) -> ing | S10: =LEN(L10) -> 6 | T10: =A10&"|"&B10&"|"&F10 -> 9|40544|8 | U10: =COUNTIF(K:K,"weekend") -> 610 | V10: =SUMIF($K:$K,"weekend",$J:$J) -> 120.1 | W10: =STDEV($J:$J) -> 0.081303845 | X10: =CORREL(J:J,F:F) -> 0.16514795
A11: 10 | B11: 40544 | C11: 1 | D11: 0 | E11: 1 | F11: 9 | G11: FALSE | H11: 6 | I11: 1 | J11: 0.32 | K11: =IF(H11=0,"weekend",IF(H11=6,"weekend","weekend")) -> weekend | L11: =IF(C11=1,"Spring",IF(C11=2,"Summer",IF(C11=3,"Fall","Winter"))) -> Spring | M11: =SUM(J11:J35) -> 10.4 | N11: =AVERAGE(J11:J620) -> 0.19640599 | O11: =COUNT(J11:J620) -> 601 | P11: =TEXT(J11,"0.00") -> 0.32 | Q11: =LEFT(L11,3) -> Spr | R11: =RIGHT(L11,3) -> ing | S11: =LEN(L11) -> 6 | T11: =A11&"|"&B11&"|"&F11 -> 10|40544|9 | U11: =COUNTIF(K:K,"weekend") -> 610 | V11: =SUMIF($K:$K,"weekend",$J:$J) -> 120.1 | W11: =STDEV($J:$J) -> 0.081303845 | X11: =CORREL(J:J,F:F) -> 0.16514795
A12: 11 | B12: 40544 | C12: 1 | D12: 0 | E12: 1 | F12: 10 | G12: FALSE | H12: 6 | I12: 1 | J12: 0.38 | K12: =IF(H12=0,"weekend",IF(H12=6,"weekend","weekend")) -> weekend | L12: =IF(C12=1,"Spring",IF(C12=2,"Summer",IF(C12=3,"Fall","Winter"))) -> Spring | M12: =SUM(J12:J36) -> 10.44 | N12: =AVERAGE(J12:J621) -> 0.1962 | O12: =COUNT(J12:J621) -> 600 | P12: =TEXT(J12,"0.00") -> 0.38 | Q12: =LEFT(L12,3) -> Spr | R12: =RIGHT(L12,3) -> ing | S12: =LEN(L12) -> 6 | T12: =A12&"|"&B12&"|"&F12 -> 11|40544|10 | U12: =COUNTIF(K:K,"weekend") -> 610 | V12: =SUMIF($K:$K,"weekend",$J:$J) -> 120.1 | W12: =STDEV($J:$J) -> 0.081303845 | X12: =CORREL(J:J,F:F) -> 0.16514795
A13: 12 | B13: 40544 | C13: 1 | D13: 0 | E13: 1 | F13: 11 | G13: FALSE | H13: 6 | I13: 1 | J13: 0.36 | K13: =IF(H13=0,"weekend",IF(H13=6,"weekend","weekend")) -> weekend | L13: =IF(C13=1,"Spring",IF(C13=2,"Summer",IF(C13=3,"Fall","Winter"))) -> Spring | M13: =SUM(J13:J37) -> 10.42 | N13: =AVERAGE(J13:J622) -> 0.19589316 | O13: =COUNT(J13:J622) -> 599 | P13: =TEXT(J13,"0.00") -> 0.36 | Q13: =LEFT(L13,3) -> Spr | R13: =RIGHT(L13,3) -> ing | S13: =LEN(L13) -> 6 | T13: =A13&"|"&B13&"|"&F13 -> 12|40544|11 | U13: =COUNTIF(K:K,"weekend") -> 610 | V13: =SUMIF($K:$K,"weekend",$J:$J) -> 120.1 | W13: =STDEV($J:$J) -> 0.081303845 | X13: =CORREL(J:J,F:F) -> 0.16514795
... A278: 277 | B278: 40878 | C278: 1 | D278: 0 | E278: 1 | F278: 23 | G278: FALSE | H278: 3 | I278: 1 | J278: 0.14 | K278: =IF(H278=0,"weekend",IF(H278=6,"weekend","weekend")) -> weekend | L278: =IF(C278=1,"Spring",IF(C278=2,"Summer",IF(C278=3,"Fall","Winter"))) -> Spring | M278: =SUM(J278:J302) -> 4.1 | N278: =AVERAGE(J278:J887) -> 0.1851497 | O278: =COUNT(J278:J887) -> 334 | P278: =TEXT(J278,"0.00") -> 0.14 | Q278: =LEFT(L278,3) -> Spr | R278: =RIGHT(L278,3) -> ing | S278: =LEN(L278) -> 6 | T278: =A278&"|"&B278&"|"&F278 -> 277|40878|23 | U278: =COUNTIF(K:K,"weekend") -> 610 | V278: =SUMIF($K:$K,"weekend",$J:$J) -> 120.1 | W278: =STDEV($J:$J) -> 0.081303845 | X278: =CORREL(J:J,F:F) -> 0.16514795
A279: 278 | B279: 13-01-2011 | C279: 1 | D279: 0 | E279: 1 | F279: 0 | G279: FALSE | H279: 4 | I279: 1 | J279: 0.14 | K279: =IF(H279=0,"weekend",IF(H279=6,"weekend","weekend")) -> weekend | L279: =IF(C279=1,"Spring",IF(C279=2,"Summer",IF(C279=3,"Fall","Winter"))) -> Spring | M279: =SUM(J279:J303) -> 4.08 | N279: =AVERAGE(J279:J888) -> 0.18528529 | O279: =COUNT(J279:J888) -> 333 | P279: =TEXT(J279,"0.00") -> 0.14 | Q279: =LEFT(L279,3) -> Spr | R279: =RIGHT(L279,3) -> ing | S279: =LEN(L279) -> 6 | T279: =A279&"|"&B279&"|"&F279 -> 278|13-01-2011|0 | U279: =COUNTIF(K:K,"weekend") -> 610 | V279: =SUMIF($K:$K,"weekend",$J:$J) -> 120.1 | W279: =STDEV($J:$J) -> 0.081303845 | X279: =CORREL(J:J,F:F) -> 0.16514795
A280: 279 | B280: 13-01-2011 | C280: 1 | D280: 0 | E280: 1 | F280: 1 | G280: FALSE | H280: 4 | I280: 1 | J280: 0.14 | K280: =IF(H280=0,"weekend",IF(H280=6,"weekend","weekend")) -> weekend | L280: =IF(C280=1,"Spring",IF(C280=2,"Summer",IF(C280=3,"Fall","Winter"))) -> Spring | M280: =SUM(J280:J304) -> 4.04 | N280: =AVERAGE(J280:J889) -> 0.18542169 | O280: =COUNT(J280:J889) -> 332 | P280: =TEXT(J280,"0.00") -> 0.14 | Q280: =LEFT(L280,3) -> Spr | R280: =RIGHT(L280,3) -> ing | S280: =LEN(L280) -> 6 | T280: =A280&"|"&B280&"|"&F280 -> 279|13-01-2011|1 | U280: =COUNTIF(K:K,"weekend") -> 610 | V280: =SUMIF($K:$K,"weekend",$J:$J) -> 120.1 | W280: =STDEV($J:$J) -> 0.081303845 | X280: =CORREL(J:J,F:F) -> 0.16514795
A281: 280 | B281: 13-01-2011 | C281: 1 | D281: 0 | E281: 1 | F281: 2 | G281: FALSE | H281: 4 | I281: 1 | J281: 0.14 | K281: =IF(H281=0,"weekend",IF(H281=6,"weekend","weekend")) -> weekend | L281: =IF(C281=1,"Spring",IF(C281=2,"Summer",IF(C281=3,"Fall","Winter"))) -> Spring | M281: =SUM(J281:J305) -> 4 | N281: =AVERAGE(J281:J890) -> 0.18555891 | O281: =COUNT(J281:J890) -> 331 | P281: =TEXT(J281,"0.00") -> 0.14 | Q281: =LEFT(L281,3) -> Spr | R281: =RIGHT(L281,3) -> ing | S281: =LEN(L281) -> 6 | T281: =A281&"|"&B281&"|"&F281 -> 280|13-01-2011|2 | U281: =COUNTIF(K:K,"weekend") -> 610 | V281: =SUMIF($K:$K,"weekend",$J:$J) -> 120.1 | W281: =STDEV($J:$J) -> 0.081303845 | X281: =CORREL(J:J,F:F) -> 0.16514795
A282: 281 | B282: 13-01-2011 | C282: 1 | D282: 0 | E282: 1 | F282: 3 | G282: FALSE | H282: 4 | I282: 1 | J282: 0.14 | K282: =IF(H282=0,"weekend",IF(H282=6,"weekend","weekend")) -> weekend | L282: =IF(C282=1,"Spring",IF(C282=2,"Summer",IF(C282=3,"Fall","Winter"))) -> Spring | M282: =SUM(J282:J306) -> 3.96 | N282: =AVERAGE(J282:J891) -> 0.18569697 | O282: =COUNT(J282:J891) -> 330 | P282: =TEXT(J282,"0.00") -> 0.14 | Q282: =LEFT(L282,3) -> Spr | R282: =RIGHT(L282,3) -> ing | S282: =LEN(L282) -> 6 | T282: =A282&"|"&B282&"|"&F282 -> 281|13-01-2011|3 | U282: =COUNTIF(K:K,"weekend") -> 610 | V282: =SUMIF($K:$K,"weekend",$J:$J) -> 120.1 | W282: =STDEV($J:$J) -> 0.081303845 | X282: =CORREL(J:J,F:F) -> 0.16514795
A283: 282 | B283: 13-01-2011 | C283: 1 | D283: 0 | E283: 1 | F283: 4 | G283: FALSE | H283: 4 | I283: 1 | J283: 0.14 | K283: =IF(H283=0,"weekend",IF(H283=6,"weekend","weekend")) -> weekend | L283: =IF(C283=1,"Spring",IF(C283=2,"Summer",IF(C283=3,"Fall","Winter"))) -> Spring | M283: =SUM(J283:J307) -> 3.92 | N283: =AVERAGE(J283:J892) -> 0.18583587 | O283: =COUNT(J283:J892) -> 329 | P283: =TEXT(J283,"0.00") -> 0.14 | Q283: =LEFT(L283,3) -> Spr | R283: =RIGHT(L283,3) -> ing | S283: =LEN(L283) -> 6 | T283: =A283&"|"&B283&"|"&F283 -> 282|13-01-2011|4 | U283: =COUNTIF(K:K,"weekend") -> 610 | V283: =SUMIF($K:$K,"weekend",$J:$J) -> 120.1 | W283: =STDEV($J:$J) -> 0.081303845 | X283: =CORREL(J:J,F:F) -> 0.16514795
A284: 283 | B284: 13-01-2011 | C284: 1 | D284: 0 | E284: 1 | F284: 5 | G284: FALSE | H284: 4 | I284: 1 | J284: 0.14 | K284: =IF(H284=0,"weekend",IF(H284=6,"weekend","weekend")) -> weekend | L284: =IF(C284=1,"Spring",IF(C284=2,"Summer",IF(C284=3,"Fall","Winter"))) -> Spring | M284: =SUM(J284:J308) -> 3.88 | N284: =AVERAGE(J284:J893) -> 0.18597561 | O284: =COUNT(J284:J893) -> 328 | P284: =TEXT(J284,"0.00") -> 0.14 | Q284: =LEFT(L284,3) -> Spr | R284: =RIGHT(L284,3) -> ing | S284: =LEN(L284) -> 6 | T284: =A284&"|"&B284&"|"&F284 -> 283|13-01-2011|5 | U284: =COUNTIF(K:K,"weekend") -> 610 | V284: =SUMIF($K:$K,"weekend",$J:$J) -> 120.1 | W284: =STDEV($J:$J) -> 0.081303845 | X284: =CORREL(J:J,F:F) -> 0.16514795
A285: 284 | B285: 13-01-2011 | C285: 1 | D285: 0 | E285: 1 | F285: 6 | G285: FALSE | H285: 4 | I285: 1 | J285: 0.12 | K285: =IF(H285=0,"weekend",IF(H285=6,"weekend","weekend")) -> weekend | L285: =IF(C285=1,"Spring",IF(C285=2,"Summer",IF(C285=3,"Fall","Winter"))) -> Spring | M285: =SUM(J285:J309) -> 3.84 | N285: =AVERAGE(J285:J894) -> 0.18611621 | O285: =COUNT(J285:J894) -> 327 | P285: =TEXT(J285,"0.00") -> 0.12 | Q285: =LEFT(L285,3) -> Spr | R285: =RIGHT(L285,3) -> ing | S285: =LEN(L285) -> 6 | T285: =A285&"|"&B285&"|"&F285 -> 284|13-01-2011|6 | U285: =COUNTIF(K:K,"weekend") -> 610 | V285: =SUMIF($K:$K,"weekend",$J:$J) -> 120.1 | W285: =STDEV($J:$J) -> 0.081303845 | X285: =CORREL(J:J,F:F) -> 0.16514795
A286: 285 | B286: 13-01-2011 | C286: 1 | D286: 0 | E286: 1 | F286: 7 | G286: FALSE | H286: 4 | I286: 1 | J286: 0.12 | K286: =IF(H286=0,"weekend",IF(H286=6,"weekend","weekend")) -> weekend | L286: =IF(C286=1,"Spring",IF(C286=2,"Summer",IF(C286=3,"Fall","Winter"))) -> Spring | M286: =SUM(J286:J310) -> 3.84 | N286: =AVERAGE(J286:J895) -> 0.18631902 | O286: =COUNT(J286:J895) -> 326 | P286: =TEXT(J286,"0.00") -> 0.12 | Q286: =LEFT(L286,3) -> Spr | R286: =RIGHT(L286,3) -> ing | S286: =LEN(L286) -> 6 | T286: =A286&"|"&B286&"|"&F286 -> 285|13-01-2011|7 | U286: =COUNTIF(K:K,"weekend") -> 610 | V286: =SUMIF($K:$K,"weekend",$J:$J) -> 120.1 | W286: =STDEV($J:$J) -> 0.081303845 | X286: =CORREL(J:J,F:F) -> 0.16514795
A287: 286 | B287: 13-01-2011 | C287: 1 | D287: 0 | E287: 1 | F287: 8 | G287: FALSE | H287: 4 | I287: 1 | J287: 0.14 | K287: =IF(H287=0,"weekend",IF(H287=6,"weekend","weekend")) -> weekend | L287: =IF(C287=1,"Spring",IF(C287=2,"Summer",IF(C287=3,"Fall","Winter"))) -> Spring | M287: =SUM(J287:J311) -> 3.86 | N287: =AVERAGE(J287:J896) -> 0.18652308 | O287: =COUNT(J287:J896) -> 325 | P287: =TEXT(J287,"0.00") -> 0.14 | Q287: =LEFT(L287,3) -> Spr | R287: =RIGHT(L287,3) -> ing | S287: =LEN(L287) -> 6 | T287: =A287&"|"&B287&"|"&F287 -> 286|13-01-2011|8 | U287: =COUNTIF(K:K,"weekend") -> 610 | V287: =SUMIF($K:$K,"weekend",$J:$J) -> 120.1 | W287: =STDEV($J:$J) -> 0.081303845 | X287: =CORREL(J:J,F:F) -> 0.16514795
A288: 287 | B288: 13-01-2011 | C288: 1 | D288: 0 | E288: 1 | F288: 9 | G288: FALSE | H288: 4 | I288: 1 | J288: 0.14 | K288: =IF(H288=0,"weekend",IF(H288=6,"weekend","weekend")) -> weekend | L288: =IF(C288=1,"Spring",IF(C288=2,"Summer",IF(C288=3,"Fall","Winter"))) -> Spring | M288: =SUM(J288:J312) -> 3.9 | N288: =AVERAGE(J288:J897) -> 0.18666667 | O288: =COUNT(J288:J897) -> 324 | P288: =TEXT(J288,"0.00") -> 0.14 | Q288: =LEFT(L288,3) -> Spr | R288: =RIGHT(L288,3) -> ing | S288: =LEN(L288) -> 6 | T288: =A288&"|"&B288&"|"&F288 -> 287|13-01-2011|9 | U288: =COUNTIF(K:K,"weekend") -> 610 | V288: =SUMIF($K:$K,"weekend",$J:$J) -> 120.1 | W288: =STDEV($J:$J) -> 0.081303845 | X288: =CORREL(J:J,F:F) -> 0.16514795
A289: 288 | B289: 13-01-2011 | C289: 1 | D289: 0 | E289: 1 | F289: 10 | G289: FALSE | H289: 4 | I289: 2 | J289: 0.16 | K289: =IF(H289=0,"weekend",IF(H289=6,"weekend","weekend")) -> weekend | L289: =IF(C289=1,"Spring",IF(C289=2,"Summer",IF(C289=3,"Fall","Winter"))) -> Spring | M289: =SUM(J289:J313) -> 3.94 | N289: =AVERAGE(J289:J898) -> 0.18681115 | O289: =COUNT(J289:J898) -> 323 | P289: =TEXT(J289,"0.00") -> 0.16 | Q289: =LEFT(L289,3) -> Spr | R289: =RIGHT(L289,3) -> ing | S289: =LEN(L289) -> 6 | T289: =A289&"|"&B289&"|"&F289 -> 288|13-01-2011|10 | U289: =COUNTIF(K:K,"weekend") -> 610 | V289: =SUMIF($K:$K,"weekend",$J:$J) -> 120.1 | W289: =STDEV($J:$J) -> 0.081303845 | X289: =CORREL(J:J,F:F) -> 0.16514795
A290: 289 | B290: 13-01-2011 | C290: 1 | D290: 0 | E290: 1 | F290: 11 | G290: FALSE | H290: 4 | I290: 2 | J290: 0.2 | K290: =IF(H290=0,"weekend",IF(H290=6,"weekend","weekend")) -> weekend | L290: =IF(C290=1,"Spring",IF(C290=2,"Summer",IF(C290=3,"Fall","Winter"))) -> Spring | M290: =SUM(J290:J314) -> 3.98 | N290: =AVERAGE(J290:J899) -> 0.18689441 | O290: =COUNT(J290:J899) -> 322 | P290: =TEXT(J290,"0.00") -> 0.20 | Q290: =LEFT(L290,3) -> Spr | R290: =RIGHT(L290,3) -> ing | S290: =LEN(L290) -> 6 | T290: =A290&"|"&B290&"|"&F290 -> 289|13-01-2011|11 | U290: =COUNTIF(K:K,"weekend") -> 610 | V290: =SUMIF($K:$K,"weekend",$J:$J) -> 120.1 | W290: =STDEV($J:$J) -> 0.081303845 | X290: =CORREL(J:J,F:F) -> 0.16514795
... A611: 610 | B611: 28-01-2011 | C611: 1 | D611: 0 | E611: 1 | F611: 15 | G611: FALSE | H611: 5 | I611: 2 | J611: 0.2 | K611: =IF(H611=0,"weekend",IF(H611=6,"weekend","weekend")) -> weekend | L611: =IF(C611=1,"Spring",IF(C611=2,"Summer",IF(C611=3,"Fall","Winter"))) -> Spring | M611: =SUM(J611:J635) -> 0.2 | N611: =AVERAGE(J611:J1220) -> 0.2 | O611: =COUNT(J611:J1220) -> 1 | P611: =TEXT(J611,"0.00") -> 0.20 | Q611: =LEFT(L611,3) -> Spr | R611: =RIGHT(L611,3) -> ing | S611: =LEN(L611) -> 6 | T611: =A611&"|"&B611&"|"&F611 -> 610|28-01-2011|15 | U611: =COUNTIF(K:K,"weekend") -> 610 | V611: =SUMIF($K:$K,"weekend",$J:$J) -> 120.1 | W611: =STDEV($J:$J) -> 0.081303845 | X611: =CORREL(J:J,F:F) -> 0.16514795

Sheet Sheet1
A1: instant | B1: dteday | C1: season | D1: yr | E1: mnth | F1: hr | G1: holiday | H1: weekday | I1: weathersit | J1: temp | K1: DayType | L1: SeasonName | M1: Total temp | N1: Avg Temp | O1: Weekend Count | P1: Temp in text | Q1: Left Text | R1: Right Text | S1: Text lenght | T1: Column1 | U1: Column2 | V1: atmp | W1: Hum | X1: cnt
A2: 1 | B2: 40544 | C2: 1 | D2: 0 | E2: 1 | F2: 0 | G2: FALSE | H2: 6 | I2: 1 | J2: 0.24 | K2: =IF(H2=0,"weekend",IF(H2=6,"weekend","weekend")) -> weekend | L2: =IF(C2=1,"Spring",IF(C2=2,"Summer",IF(C2=3,"Fall","Winter"))) -> Spring | M2: =SUM(J2:J26) -> 8.72 | N2: =AVERAGE(J2:J611) -> 0.19688525 | O2: =COUNT(J2:J611) -> 610 | P2: =TEXT(J2,"0.00") -> 0.24 | Q2: =LEFT(L2,3) -> Spr | R2: =RIGHT(L2,3) -> ing | S2: =LEN(L2) -> 6 | T2: =A2&"|"&B2&"|"&F2 -> 1|40544|0 | V2: =VLOOKUP(A2,Sheet2!A:H,3,FALSE) -> 0.2727 | W2: =VLOOKUP(A2,Sheet2!A:H,4,FALSE) -> 0.8 | X2: =VLOOKUP(A2,Sheet2!A:H,7,FALSE) -> 32
A3: 2 | B3: 40544 | C3: 1 | D3: 0 | E3: 1 | F3: 1 | G3: FALSE | H3: 6 | I3: 1 | J3: 0.22 | K3: =IF(H3=0,"weekend",IF(H3=6,"weekend","weekend")) -> weekend | L3: =IF(C3=1,"Spring",IF(C3=2,"Summer",IF(C3=3,"Fall","Winter"))) -> Spring | M3: =SUM(J3:J27) -> 8.92 | N3: =AVERAGE(J3:J612) -> 0.19681445 | O3: =COUNT(J3:J612) -> 609 | P3: =TEXT(J3,"0.00") -> 0.22 | Q3: =LEFT(L3,3) -> Spr | R3: =RIGHT(L3,3) -> ing | S3: =LEN(L3) -> 6 | T3: =A3&"|"&B3&"|"&F3 -> 2|40544|1 | V3: =VLOOKUP(A3,Sheet2!A:H,3,FALSE) -> 0.2727 | W3: =VLOOKUP(A3,Sheet2!A:H,4,FALSE) -> 0.8 | X3: =VLOOKUP(A3,Sheet2!A:H,7,FALSE) -> 27
A4: 3 | B4: 40544 | C4: 1 | D4: 0 | E4: 1 | F4: 2 | G4: FALSE | H4: 6 | I4: 1 | J4: 0.22 | K4: =IF(H4=0,"weekend",IF(H4=6,"weekend","weekend")) -> weekend | L4: =IF(C4=1,"Spring",IF(C4=2,"Summer",IF(C4=3,"Fall","Winter"))) -> Spring | M4: =SUM(J4:J28) -> 9.12 | N4: =AVERAGE(J4:J613) -> 0.19677632 | O4: =COUNT(J4:J613) -> 608 | P4: =TEXT(J4,"0.00") -> 0.22 | Q4: =LEFT(L4,3) -> Spr | R4: =RIGHT(L4,3) -> ing | S4: =LEN(L4) -> 6 | T4: =A4&"|"&B4&"|"&F4 -> 3|40544|2 | V4: =VLOOKUP(A4,Sheet2!A:H,3,FALSE) -> 0.2879 | W4: =VLOOKUP(A4,Sheet2!A:H,4,FALSE) -> 0.75 | X4: =VLOOKUP(A4,Sheet2!A:H,7,FALSE) -> 10
A5: 4 | B5: 40544 | C5: 1 | D5: 0 | E5: 1 | F5: 3 | G5: FALSE | H5: 6 | I5: 1 | J5: 0.24 | K5: =IF(H5=0,"weekend",IF(H5=6,"weekend","weekend")) -> weekend | L5: =IF(C5=1,"Spring",IF(C5=2,"Summer",IF(C5=3,"Fall","Winter"))) -> Spring | M5: =SUM(J5:J29) -> 9.36 | N5: =AVERAGE(J5:J614) -> 0.19673806 | O5: =COUNT(J5:J614) -> 607 | P5: =TEXT(J5,"0.00") -> 0.24 | Q5: =LEFT(L5,3) -> Spr | R5: =RIGHT(L5,3) -> ing | S5: =LEN(L5) -> 6 | T5: =A5&"|"&B5&"|"&F5 -> 4|40544|3 | V5: =VLOOKUP(A5,Sheet2!A:H,3,FALSE) -> 0.2879 | W5: =VLOOKUP(A5,Sheet2!A:H,4,FALSE) -> 0.75 | X5: =VLOOKUP(A5,Sheet2!A:H,7,FALSE) -> 1
A6: 5 | B6: 40544 | C6: 1 | D6: 0 | E6: 1 | F6: 4 | G6: FALSE | H6: 6 | I6: 1 | J6: 0.24 | K6: =IF(H6=0,"weekend",IF(H6=6,"weekend","weekend")) -> weekend | L6: =IF(C6=1,"Spring",IF(C6=2,"Summer",IF(C6=3,"Fall","Winter"))) -> Spring | M6: =SUM(J6:J30) -> 9.58 | N6: =AVERAGE(J6:J615) -> 0.19666667 | O6: =COUNT(J6:J615) -> 606 | P6: =TEXT(J6,"0.00") -> 0.24 | Q6: =LEFT(L6,3) -> Spr | R6: =RIGHT(L6,3) -> ing | S6: =LEN(L6) -> 6 | T6: =A6&"|"&B6&"|"&F6 -> 5|40544|4 | V6: =VLOOKUP(A6,Sheet2!A:H,3,FALSE) -> 0.2576 | W6: =VLOOKUP(A6,Sheet2!A:H,4,FALSE) -> 0.75 | X6: =VLOOKUP(A6,Sheet2!A:H,7,FALSE) -> 1
A7: 6 | B7: 40544 | C7: 1 | D7: 0 | E7: 1 | F7: 5 | G7: FALSE | H7: 6 | I7: 2 | J7: 0.24 | K7: =IF(H7=0,"weekend",IF(H7=6,"weekend","weekend")) -> weekend | L7: =IF(C7=1,"Spring",IF(C7=2,"Summer",IF(C7=3,"Fall","Winter"))) -> Spring | M7: =SUM(J7:J31) -> 9.76 | N7: =AVERAGE(J7:J616) -> 0.19659504 | O7: =COUNT(J7:J616) -> 605 | P7: =TEXT(J7,"0.00") -> 0.24 | Q7: =LEFT(L7,3) -> Spr | R7: =RIGHT(L7,3) -> ing | S7: =LEN(L7) -> 6 | T7: =A7&"|"&B7&"|"&F7 -> 6|40544|5 | V7: =VLOOKUP(A7,Sheet2!A:H,3,FALSE) -> 0.2727 | W7: =VLOOKUP(A7,Sheet2!A:H,4,FALSE) -> 0.8 | X7: =VLOOKUP(A7,Sheet2!A:H,7,FALSE) -> 0
A8: 7 | B8: 40544 | C8: 1 | D8: 0 | E8: 1 | F8: 6 | G8: FALSE | H8: 6 | I8: 1 | J8: 0.22 | K8: =IF(H8=0,"weekend",IF(H8=6,"weekend","weekend")) -> weekend | L8: =IF(C8=1,"Spring",IF(C8=2,"Summer",IF(C8=3,"Fall","Winter"))) -> Spring | M8: =SUM(J8:J32) -> 9.92 | N8: =AVERAGE(J8:J617) -> 0.19652318 | O8: =COUNT(J8:J617) -> 604 | P8: =TEXT(J8,"0.00") -> 0.22 | Q8: =LEFT(L8,3) -> Spr | R8: =RIGHT(L8,3) -> ing | S8: =LEN(L8) -> 6 | T8: =A8&"|"&B8&"|"&F8 -> 7|40544|6 | V8: =VLOOKUP(A8,Sheet2!A:H,3,FALSE) -> 0.2576 | W8: =VLOOKUP(A8,Sheet2!A:H,4,FALSE) -> 0.86 | X8: =VLOOKUP(A8,Sheet2!A:H,7,FALSE) -> 2
A9: 8 | B9: 40544 | C9: 1 | D9: 0 | E9: 1 | F9: 7 | G9: FALSE | H9: 6 | I9: 1 | J9: 0.2 | K9: =IF(H9=0,"weekend",IF(H9=6,"weekend","weekend")) -> weekend | L9: =IF(C9=1,"Spring",IF(C9=2,"Summer",IF(C9=3,"Fall","Winter"))) -> Spring | M9: =SUM(J9:J33) -> 10.1 | N9: =AVERAGE(J9:J618) -> 0.19648425 | O9: =COUNT(J9:J618) -> 603 | P9: =TEXT(J9,"0.00") -> 0.20 | Q9: =LEFT(L9,3) -> Spr | R9: =RIGHT(L9,3) -> ing | S9: =LEN(L9) -> 6 | T9: =A9&"|"&B9&"|"&F9 -> 8|40544|7 | V9: =VLOOKUP(A9,Sheet2!A:H,3,FALSE) -> 0 | W9: =VLOOKUP(A9,Sheet2!A:H,4,FALSE) -> 0.75 | X9: =VLOOKUP(A9,Sheet2!A:H,7,FALSE) -> 7
A10: 9 | B10: 40544 | C10: 1 | D10: 0 | E10: 1 | F10: 8 | G10: FALSE | H10: 6 | I10: 1 | J10: 0.24 | K10: =IF(H10=0,"weekend",IF(H10=6,"weekend","weekend")) -> weekend | L10: =IF(C10=1,"Spring",IF(C10=2,"Summer",IF(C10=3,"Fall","Winter"))) -> Spring | M10: =SUM(J10:J34) -> 10.28 | N10: =AVERAGE(J10:J619) -> 0.19647841 | O10: =COUNT(J10:J619) -> 602 | P10: =TEXT(J10,"0.00") -> 0.24 | Q10: =LEFT(L10,3) -> Spr | R10: =RIGHT(L10,3) -> ing | S10: =LEN(L10) -> 6 | T10: =A10&"|"&B10&"|"&F10 -> 9|40544|8 | V10: =VLOOKUP(A10,Sheet2!A:H,3,FALSE) -> 0.3485 | W10: =VLOOKUP(A10,Sheet2!A:H,4,FALSE) -> 0.76 | X10: =VLOOKUP(A10,Sheet2!A:H,7,FALSE) -> 6
A11: 10 | B11: 40544 | C11: 1 | D11: 0 | E11: 1 | F11: 9 | G11: FALSE | H11: 6 | I11: 1 | J11: 0.32 | K11: =IF(H11=0,"weekend",IF(H11=6,"weekend","weekend")) -> weekend | L11: =IF(C11=1,"Spring",IF(C11=2,"Summer",IF(C11=3,"Fall","Winter"))) -> Spring | M11: =SUM(J11:J35) -> 10.4 | N11: =AVERAGE(J11:J620) -> 0.19640599 | O11: =COUNT(J11:J620) -> 601 | P11: =TEXT(J11,"0.00") -> 0.32 | Q11: =LEFT(L11,3) -> Spr | R11: =RIGHT(L11,3) -> ing | S11: =LEN(L11) -> 6 | T11: =A11&"|"&B11&"|"&F11 -> 10|40544|9 | V11: =VLOOKUP(A11,Sheet2!A:H,3,FALSE) -> 0.3939 | W11: =VLOOKUP(A11,Sheet2!A:H,4,FALSE) -> 0.76 | X11: =VLOOKUP(A11,Sheet2!A:H,7,FALSE) -> 24
A12: 11 | B12: 40544 | C12: 1 | D12: 0 | E12: 1 | F12: 10 | G12: FALSE | H12: 6 | I12: 1 | J12: 0.38 | K12: =IF(H12=0,"weekend",IF(H12=6,"weekend","weekend")) -> weekend | L12: =IF(C12=1,"Spring",IF(C12=2,"Summer",IF(C12=3,"Fall","Winter"))) -> Spring | M12: =SUM(J12:J36) -> 10.44 | N12: =AVERAGE(J12:J621) -> 0.1962 | O12: =COUNT(J12:J621) -> 600 | P12: =TEXT(J12,"0.00") -> 0.38 | Q12: =LEFT(L12,3) -> Spr | R12: =RIGHT(L12,3) -> ing | S12: =LEN(L12) -> 6 | T12: =A12&"|"&B12&"|"&F12 -> 11|40544|10 | V12: =VLOOKUP(A12,Sheet2!A:H,3,FALSE) -> 0.3333 | W12: =VLOOKUP(A12,Sheet2!A:H,4,FALSE) -> 0.81 | X12: =VLOOKUP(A12,Sheet2!A:H,7,FALSE) -> 30
A13: 12 | B13: 40544 | C13: 1 | D13: 0 | E13: 1 | F13: 11 | G13: FALSE | H13: 6 | I13: 1 | J13: 0.36 | K13: =IF(H13=0,"weekend",IF(H13=6,"weekend","weekend")) -> weekend | L13: =IF(C13=1,"Spring",IF(C13=2,"Summer",IF(C13=3,"Fall","Winter"))) -> Spring | M13: =SUM(J13:J37) -> 10.42 | N13: =AVERAGE(J13:J622) -> 0.19589316 | O13: =COUNT(J13:J622) -> 599 | P13: =TEXT(J13,"0.00") -> 0.36 | Q13: =LEFT(L13,3) -> Spr | R13: =RIGHT(L13,3) -> ing | S13: =LEN(L13) -> 6 | T13: =A13&"|"&B13&"|"&F13 -> 12|40544|11 | V13: =VLOOKUP(A13,Sheet2!A:H,3,FALSE) -> 0.4242 | W13: =VLOOKUP(A13,Sheet2!A:H,4,FALSE) -> 0.77 | X13: =VLOOKUP(A13,Sheet2!A:H,7,FALSE) -> 55
... A278: 277 | B278: 40878 | C278: 1 | D278: 0 | E278: 1 | F278: 23 | G278: FALSE | H278: 3 | I278: 1 | J278: 0.14 | K278: =IF(H278=0,"weekend",IF(H278=6,"weekend","weekend")) -> weekend | L278: =IF(C278=1,"Spring",IF(C278=2,"Summer",IF(C278=3,"Fall","Winter"))) -> Spring | M278: =SUM(J278:J302) -> 4.1 | N278: =AVERAGE(J278:J887) -> 0.1851497 | O278: =COUNT(J278:J887) -> 334 | P278: =TEXT(J278,"0.00") -> 0.14 | Q278: =LEFT(L278,3) -> Spr | R278: =RIGHT(L278,3) -> ing | S278: =LEN(L278) -> 6 | T278: =A278&"|"&B278&"|"&F278 -> 277|40878|23 | V278: =VLOOKUP(A278,Sheet2!A:H,3,FALSE) -> 0.1212 | W278: =VLOOKUP(A278,Sheet2!A:H,4,FALSE) -> 0.59 | X278: =VLOOKUP(A278,Sheet2!A:H,7,FALSE) -> 6
A279: 278 | B279: 13-01-2011 | C279: 1 | D279: 0 | E279: 1 | F279: 0 | G279: FALSE | H279: 4 | I279: 1 | J279: 0.14 | K279: =IF(H279=0,"weekend",IF(H279=6,"weekend","weekend")) -> weekend | L279: =IF(C279=1,"Spring",IF(C279=2,"Summer",IF(C279=3,"Fall","Winter"))) -> Spring | M279: =SUM(J279:J303) -> 4.08 | N279: =AVERAGE(J279:J888) -> 0.18528529 | O279: =COUNT(J279:J888) -> 333 | P279: =TEXT(J279,"0.00") -> 0.14 | Q279: =LEFT(L279,3) -> Spr | R279: =RIGHT(L279,3) -> ing | S279: =LEN(L279) -> 6 | T279: =A279&"|"&B279&"|"&F279 -> 278|13-01-2011|0 | V279: =VLOOKUP(A279,Sheet2!A:H,3,FALSE) -> 0.1212 | W279: =VLOOKUP(A279,Sheet2!A:H,4,FALSE) -> 0.5 | X279: =VLOOKUP(A279,Sheet2!A:H,7,FALSE) -> 2
A280: 279 | B280: 13-01-2011 | C280: 1 | D280: 0 | E280: 1 | F280: 1 | G280: FALSE | H280: 4 | I280: 1 | J280: 0.14 | K280: =IF(H280=0,"weekend",IF(H280=6,"weekend","weekend")) -> weekend | L280: =IF(C280=1,"Spring",IF(C280=2,"Summer",IF(C280=3,"Fall","Winter"))) -> Spring | M280: =SUM(J280:J304) -> 4.04 | N280: =AVERAGE(J280:J889) -> 0.18542169 | O280: =COUNT(J280:J889) -> 332 | P280: =TEXT(J280,"0.00") -> 0.14 | Q280: =LEFT(L280,3) -> Spr | R280: =RIGHT(L280,3) -> ing | S280: =LEN(L280) -> 6 | T280: =A280&"|"&B280&"|"&F280 -> 279|13-01-2011|1 | V280: =VLOOKUP(A280,Sheet2!A:H,3,FALSE) -> 0.1212 | W280: =VLOOKUP(A280,Sheet2!A:H,4,FALSE) -> 0.5 | X280: =VLOOKUP(A280,Sheet2!A:H,7,FALSE) -> 2
A281: 280 | B281: 13-01-2011 | C281: 1 | D281: 0 | E281: 1 | F281: 2 | G281: FALSE | H281: 4 | I281: 1 | J281: 0.14 | K281: =IF(H281=0,"weekend",IF(H281=6,"weekend","weekend")) -> weekend | L281: =IF(C281=1,"Spring",IF(C281=2,"Summer",IF(C281=3,"Fall","Winter"))) -> Spring | M281: =SUM(J281:J305) -> 4 | N281: =AVERAGE(J281:J890) -> 0.18555891 | O281: =COUNT(J281:J890) -> 331 | P281: =TEXT(J281,"0.00") -> 0.14 | Q281: =LEFT(L281,3) -> Spr | R281: =RIGHT(L281,3) -> ing | S281: =LEN(L281) -> 6 | T281: =A281&"|"&B281&"|"&F281 -> 280|13-01-2011|2 | V281: =VLOOKUP(A281,Sheet2!A:H,3,FALSE) -> 0.1212 | W281: =VLOOKUP(A281,Sheet2!A:H,4,FALSE) -> 0.5 | X281: =VLOOKUP(A281,Sheet2!A:H,7,FALSE) -> 3
A282: 281 | B282: 13-01-2011 | C282: 1 | D282: 0 | E282: 1 | F282: 3 | G282: FALSE | H282: 4 | I282: 1 | J282: 0.14 | K282: =IF(H282=0,"weekend",IF(H282=6,"weekend","weekend")) -> weekend | L282: =IF(C282=1,"Spring",IF(C282=2,"Summer",IF(C282=3,"Fall","Winter"))) -> Spring | M282: =SUM(J282:J306) -> 3.96 | N282: =AVERAGE(J282:J891) -> 0.18569697 | O282: =COUNT(J282:J891) -> 330 | P282: =TEXT(J282,"0.00") -> 0.14 | Q282: =LEFT(L282,3) -> Spr | R282: =RIGHT(L282,3) -> ing | S282: =LEN(L282) -> 6 | T282: =A282&"|"&B282&"|"&F282 -> 281|13-01-2011|3 | V282: =VLOOKUP(A282,Sheet2!A:H,3,FALSE) -> 0.1212 | W282: =VLOOKUP(A282,Sheet2!A:H,4,FALSE) -> 0.5 | X282: =VLOOKUP(A282,Sheet2!A:H,7,FALSE) -> 4
A283: 282 | B283: 13-01-2011 | C283: 1 | D283: 0 | E283: 1 | F283: 4 | G283: FALSE | H283: 4 | I283: 1 | J283: 0.14 | K283: =IF(H283=0,"weekend",IF(H283=6,"weekend","weekend")) -> weekend | L283: =IF(C283=1,"Spring",IF(C283=2,"Summer",IF(C283=3,"Fall","Winter"))) -> Spring | M283: =SUM(J283:J307) -> 3.92 | N283: =AVERAGE(J283:J892) -> 0.18583587 | O283: =COUNT(J283:J892) -> 329 | P283: =TEXT(J283,"0.00") -> 0.14 | Q283: =LEFT(L283,3) -> Spr | R283: =RIGHT(L283,3) -> ing | S283: =LEN(L283) -> 6 | T283: =A283&"|"&B283&"|"&F283 -> 282|13-01-2011|4 | V283: =VLOOKUP(A283,Sheet2!A:H,3,FALSE) -> 0.1212 | W283: =VLOOKUP(A283,Sheet2!A:H,4,FALSE) -> 0.5 | X283: =VLOOKUP(A283,Sheet2!A:H,7,FALSE) -> 3
A284: 283 | B284: 13-01-2011 | C284: 1 | D284: 0 | E284: 1 | F284: 5 | G284: FALSE | H284: 4 | I284: 1 | J284: 0.14 | K284: =IF(H284=0,"weekend",IF(H284=6,"weekend","weekend")) -> weekend | L284: =IF(C284=1,"Spring",IF(C284=2,"Summer",IF(C284=3,"Fall","Winter"))) -> Spring | M284: =SUM(J284:J308) -> 3.88 | N284: =AVERAGE(J284:J893) -> 0.18597561 | O284: =COUNT(J284:J893) -> 328 | P284: =TEXT(J284,"0.00") -> 0.14 | Q284: =LEFT(L284,3) -> Spr | R284: =RIGHT(L284,3) -> ing | S284: =LEN(L284) -> 6 | T284: =A284&"|"&B284&"|"&F284 -> 283|13-01-2011|5 | V284: =VLOOKUP(A284,Sheet2!A:H,3,FALSE) -> 0.1515 | W284: =VLOOKUP(A284,Sheet2!A:H,4,FALSE) -> 0.54 | X284: =VLOOKUP(A284,Sheet2!A:H,7,FALSE) -> 28
A285: 284 | B285: 13-01-2011 | C285: 1 | D285: 0 | E285: 1 | F285: 6 | G285: FALSE | H285: 4 | I285: 1 | J285: 0.12 | K285: =IF(H285=0,"weekend",IF(H285=6,"weekend","weekend")) -> weekend | L285: =IF(C285=1,"Spring",IF(C285=2,"Summer",IF(C285=3,"Fall","Winter"))) -> Spring | M285: =SUM(J285:J309) -> 3.84 | N285: =AVERAGE(J285:J894) -> 0.18611621 | O285: =COUNT(J285:J894) -> 327 | P285: =TEXT(J285,"0.00") -> 0.12 | Q285: =LEFT(L285,3) -> Spr | R285: =RIGHT(L285,3) -> ing | S285: =LEN(L285) -> 6 | T285: =A285&"|"&B285&"|"&F285 -> 284|13-01-2011|6 | V285: =VLOOKUP(A285,Sheet2!A:H,3,FALSE) -> 0.1515 | W285: =VLOOKUP(A285,Sheet2!A:H,4,FALSE) -> 0.54 | X285: =VLOOKUP(A285,Sheet2!A:H,7,FALSE) -> 72
A286: 285 | B286: 13-01-2011 | C286: 1 | D286: 0 | E286: 1 | F286: 7 | G286: FALSE | H286: 4 | I286: 1 | J286: 0.12 | K286: =IF(H286=0,"weekend",IF(H286=6,"weekend","weekend")) -> weekend | L286: =IF(C286=1,"Spring",IF(C286=2,"Summer",IF(C286=3,"Fall","Winter"))) -> Spring | M286: =SUM(J286:J310) -> 3.84 | N286: =AVERAGE(J286:J895) -> 0.18631902 | O286: =COUNT(J286:J895) -> 326 | P286: =TEXT(J286,"0.00") -> 0.12 | Q286: =LEFT(L286,3) -> Spr | R286: =RIGHT(L286,3) -> ing | S286: =LEN(L286) -> 6 | T286: =A286&"|"&B286&"|"&F286 -> 285|13-01-2011|7 | V286: =VLOOKUP(A286,Sheet2!A:H,3,FALSE) -> 0.1364 | W286: =VLOOKUP(A286,Sheet2!A:H,4,FALSE) -> 0.5 | X286: =VLOOKUP(A286,Sheet2!A:H,7,FALSE) -> 197
A287: 286 | B287: 13-01-2011 | C287: 1 | D287: 0 | E287: 1 | F287: 8 | G287: FALSE | H287: 4 | I287: 1 | J287: 0.14 | K287: =IF(H287=0,"weekend",IF(H287=6,"weekend","weekend")) -> weekend | L287: =IF(C287=1,"Spring",IF(C287=2,"Summer",IF(C287=3,"Fall","Winter"))) -> Spring | M287: =SUM(J287:J311) -> 3.86 | N287: =AVERAGE(J287:J896) -> 0.18652308 | O287: =COUNT(J287:J896) -> 325 | P287: =TEXT(J287,"0.00") -> 0.14 | Q287: =LEFT(L287,3) -> Spr | R287: =RIGHT(L287,3) -> ing | S287: =LEN(L287) -> 6 | T287: =A287&"|"&B287&"|"&F287 -> 286|13-01-2011|8 | V287: =VLOOKUP(A287,Sheet2!A:H,3,FALSE) -> 0.1212 | W287: =VLOOKUP(A287,Sheet2!A:H,4,FALSE) -> 0.5 | X287: =VLOOKUP(A287,Sheet2!A:H,7,FALSE) -> 137
A288: 287 | B288: 13-01-2011 | C288: 1 | D288: 0 | E288: 1 | F288: 9 | G288: FALSE | H288: 4 | I288: 1 | J288: 0.14 | K288: =IF(H288=0,"weekend",IF(H288=6,"weekend","weekend")) -> weekend | L288: =IF(C288=1,"Spring",IF(C288=2,"Summer",IF(C288=3,"Fall","Winter"))) -> Spring | M288: =SUM(J288:J312) -> 3.9 | N288: =AVERAGE(J288:J897) -> 0.18666667 | O288: =COUNT(J288:J897) -> 324 | P288: =TEXT(J288,"0.00") -> 0.14 | Q288: =LEFT(L288,3) -> Spr | R288: =RIGHT(L288,3) -> ing | S288: =LEN(L288) -> 6 | T288: =A288&"|"&B288&"|"&F288 -> 287|13-01-2011|9 | V288: =VLOOKUP(A288,Sheet2!A:H,3,FALSE) -> 0.1364 | W288: =VLOOKUP(A288,Sheet2!A:H,4,FALSE) -> 0.5 | X288: =VLOOKUP(A288,Sheet2!A:H,7,FALSE) -> 36
A289: 288 | B289: 13-01-2011 | C289: 1 | D289: 0 | E289: 1 | F289: 10 | G289: FALSE | H289: 4 | I289: 2 | J289: 0.16 | K289: =IF(H289=0,"weekend",IF(H289=6,"weekend","weekend")) -> weekend | L289: =IF(C289=1,"Spring",IF(C289=2,"Summer",IF(C289=3,"Fall","Winter"))) -> Spring | M289: =SUM(J289:J313) -> 3.94 | N289: =AVERAGE(J289:J898) -> 0.18681115 | O289: =COUNT(J289:J898) -> 323 | P289: =TEXT(J289,"0.00") -> 0.16 | Q289: =LEFT(L289,3) -> Spr | R289: =RIGHT(L289,3) -> ing | S289: =LEN(L289) -> 6 | T289: =A289&"|"&B289&"|"&F289 -> 288|13-01-2011|10 | V289: =VLOOKUP(A289,Sheet2!A:H,3,FALSE) -> 0.1667 | W289: =VLOOKUP(A289,Sheet2!A:H,4,FALSE) -> 0.44 | X289: =VLOOKUP(A289,Sheet2!A:H,7,FALSE) -> 33
A290: 289 | B290: 13-01-2011 | C290: 1 | D290: 0 | E290: 1 | F290: 11 | G290: FALSE | H290: 4 | I290: 2 | J290: 0.2 | K290: =IF(H290=0,"weekend",IF(H290=6,"weekend","weekend")) -> weekend | L290: =IF(C290=1,"Spring",IF(C290=2,"Summer",IF(C290=3,"Fall","Winter"))) -> Spring | M290: =SUM(J290:J314) -> 3.98 | N290: =AVERAGE(J290:J899) -> 0.18689441 | O290: =COUNT(J290:J899) -> 322 | P290: =TEXT(J290,"0.00") -> 0.20 | Q290: =LEFT(L290,3) -> Spr | R290: =RIGHT(L290,3) -> ing | S290: =LEN(L290) -> 6 | T290: =A290&"|"&B290&"|"&F290 -> 289|13-01-2011|11 | V290: =VLOOKUP(A290,Sheet2!A:H,3,FALSE) -> 0.1667 | W290: =VLOOKUP(A290,Sheet2!A:H,4,FALSE) -> 0.44 | X290: =VLOOKUP(A290,Sheet2!A:H,7,FALSE) -> 49
... A611: 610 | B611: 28-01-2011 | C611: 1 | D611: 0 | E611: 1 | F611: 15 | G611: FALSE | H611: 5 | I611: 2 | J611: 0.2 | K611: =IF(H611=0,"weekend",IF(H611=6,"weekend","weekend")) -> weekend | L611: =IF(C611=1,"Spring",IF(C611=2,"Summer",IF(C611=3,"Fall","Winter"))) -> Spring | M611: =SUM(J611:J635) -> 0.2 | N611: =AVERAGE(J611:J1220) -> 0.2 | O611: =COUNT(J611:J1220) -> 1 | P611: =TEXT(J611,"0.00") -> 0.20 | Q611: =LEFT(L611,3) -> Spr | R611: =RIGHT(L611,3) -> ing | S611: =LEN(L611) -> 6 | T611: =A611&"|"&B611&"|"&F611 -> 610|28-01-2011|15 | V611: =VLOOKUP(A611,Sheet2!A:H,3,FALSE) -> #N/A | W611: =VLOOKUP(A611,Sheet2!A:H,4,FALSE) -> #N/A | X611: =VLOOKUP(A611,Sheet2!A:H,7,FALSE) -> #N/A

Sheet User Demand Over Time
A3: instant | B3: Sum of cnt
A4: 1 | B4: 16
A5: 2 | B5: 40
A6: 3 | B6: 32
A7: 4 | B7: 13
A8: 5 | B8: 1
A9: 6 | B9: 1
A10: 7 | B10: 2
A11: 8 | B11: 3
A12: 9 | B12: 8
A13: 10 | B13: 14
A14: 11 | B14: 36
A15: 12 | B15: 56
... A613: 610 | B613: 41
A614: Grand Total | B614: 33898

Sheet Average User Demand by Humidity
A3: hum | B3: Sum of Avg cnt
A4: 0.21 | B4: 54.260563
A5: 0.25 | B5: 54.12766
A6: 0.26 | B6: 220.59345
A7: 0.27 | B7: 54.426573
A8: 0.28 | B8: 499.7967
A9: 0.29 | B9: 55.143187
A10: 0.3 | B10: 503.13231
A11: 0.32 | B11: 223.84006
A12: 0.33 | B12: 277.41759
A13: 0.34 | B13: 169.85357
A14: 0.35 | B14: 503.64483
A15: 0.36 | B15: 561.85008
... A64: 1 | B64: 56.299658
A65: Grand Total | B65: 33972.911

Sheet Casual vs Registered Users
A3: Sum of registered | B3: Sum of casual
A4: 31152 | B4: 2746

Sheet dataset_2
A1: Unnamed | B1: instant | C1: atemp | D1: hum | E1: windspeed | F1: casual | G1: registered | H1: cnt | I1: Total atemp | J1: Avg atemp | K1: count atemp | L1: total hum | M1: Avg hum | N1: count hum | O1: total cnt | P1: Avg cnt | Q1: count cnt | R1: left instant | S1: right instant | T1: lenght instant | U1: Countif | V1: sumif | W1: STdev | X1: Correl
A2: 0 | B2: 1 | C2: 0.2879 | D2: 0.81 | E2: 0 | F2: 3 | G2: 13 | H2: 16 | I2: =SUM(C2:C611) -> 121.96029 | J2: =AVERAGE(C2:C611) -> 0.19993489 | K2: =COUNT(C2:C611) -> 610 | L2: =SUM(D2:D611) -> 343.11 | M2: =AVERAGE(D2:D611) -> 0.56247541 | N2: =COUNT(D2:D611) -> 610 | O2: =SUM(H2:H611) -> 33898 | P2: =AVERAGE(H2:H611) -> 55.570492 | Q2: =COUNT(H2:H611) -> 610 | R2: =LEFT(B2,1) -> 1 | S2: =RIGHT(B2,1) -> 1 | T2: =LEN(B2) -> 1 | U2: =COUNTIF(H:H,">100") -> 89 | V2: =SUMIF(D:D,">0.8",H:H) -> 3183 | W2: =STDEV(H:H) -> 49.316802 | X2: =CORREL(C:C,H:H) -> 0.18825987
A3: 1 | B3: 2 | C3: 0.2727 | D3: 0.8 | E3: 0 | F3: 8 | G3: 32 | H3: 40 | I3: =SUM(C3:C612) -> 121.67239 | J3: =AVERAGE(C3:C612) -> 0.19979045 | K3: =COUNT(C3:C612) -> 609 | L3: =SUM(D3:D612) -> 342.3 | M3: =AVERAGE(D3:D612) -> 0.56206897 | N3: =COUNT(D3:D612) -> 609 | O3: =SUM(H3:H612) -> 33882 | P3: =AVERAGE(H3:H612) -> 55.635468 | Q3: =COUNT(H3:H612) -> 609 | R3: =LEFT(B3,1) -> 2 | S3: =RIGHT(B3,1) -> 2 | T3: =LEN(B3) -> 1 | U3: =COUNTIF(H:H,">100") -> 89 | V3: =SUMIF(D:D,">0.8",H:H) -> 3183 | W3: =STDEV(H:H) -> 49.316802 | X3: =CORREL(C:C,H:H) -> 0.18825987
A4: 2 | B4: 3 | C4: 0.2727 | D4: 0.8 | E4: 0 | F4: 5 | G4: 27 | H4: 32 | I4: =SUM(C4:C613) -> 121.39969 | J4: =AVERAGE(C4:C613) -> 0.19967053 | K4: =COUNT(C4:C613) -> 608 | L4: =SUM(D4:D613) -> 341.5 | M4: =AVERAGE(D4:D613) -> 0.56167763 | N4: =COUNT(D4:D613) -> 608 | O4: =SUM(H4:H613) -> 33842 | P4: =AVERAGE(H4:H613) -> 55.661184 | Q4: =COUNT(H4:H613) -> 608 | R4: =LEFT(B4,1) -> 3 | S4: =RIGHT(B4,1) -> 3 | T4: =LEN(B4) -> 1 | U4: =COUNTIF(H:H,">100") -> 89 | V4: =SUMIF(D:D,">0.8",H:H) -> 3183 | W4: =STDEV(H:H) -> 49.316802 | X4: =CORREL(C:C,H:H) -> 0.18825987
A5: 3 | B5: 4 | C5: 0.2879 | D5: 0.75 | E5: 0 | F5: 3 | G5: 10 | H5: 13 | I5: =SUM(C5:C614) -> 121.12699 | J5: =AVERAGE(C5:C614) -> 0.19955022 | K5: =COUNT(C5:C614) -> 607 | L5: =SUM(D5:D614) -> 340.7 | M5: =AVERAGE(D5:D614) -> 0.56128501 | N5: =COUNT(D5:D614) -> 607 | O5: =SUM(H5:H614) -> 33810 | P5: =AVERAGE(H5:H614) -> 55.700165 | Q5: =COUNT(H5:H614) -> 607 | R5: =LEFT(B5,1) -> 4 | S5: =RIGHT(B5,1) -> 4 | T5: =LEN(B5) -> 1 | U5: =COUNTIF(H:H,">100") -> 89 | V5: =SUMIF(D:D,">0.8",H:H) -> 3183 | W5: =STDEV(H:H) -> 49.316802 | X5: =CORREL(C:C,H:H) -> 0.18825987
A6: 4 | B6: 5 | C6: 0.2879 | D6: 0.75 | E6: 0 | F6: 0 | G6: 1 | H6: 1 | I6: =SUM(C6:C615) -> 120.83909 | J6: =AVERAGE(C6:C615) -> 0.19940443 | K6: =COUNT(C6:C615) -> 606 | L6: =SUM(D6:D615) -> 339.95 | M6: =AVERAGE(D6:D615) -> 0.5609736 | N6: =COUNT(D6:D615) -> 606 | O6: =SUM(H6:H615) -> 33797 | P6: =AVERAGE(H6:H615) -> 55.770627 | Q6: =COUNT(H6:H615) -> 606 | R6: =LEFT(B6,1) -> 5 | S6: =RIGHT(B6,1) -> 5 | T6: =LEN(B6) -> 1 | U6: =COUNTIF(H:H,">100") -> 89 | V6: =SUMIF(D:D,">0.8",H:H) -> 3183 | W6: =STDEV(H:H) -> 49.316802 | X6: =CORREL(C:C,H:H) -> 0.18825987
A7: 5 | B7: 6 | C7: 0.2576 | D7: 0.75 | E7: 0.0896 | F7: 0 | G7: 1 | H7: 1 | I7: =SUM(C7:C616) -> 120.55119 | J7: =AVERAGE(C7:C616) -> 0.19925816 | K7: =COUNT(C7:C616) -> 605 | L7: =SUM(D7:D616) -> 339.2 | M7: =AVERAGE(D7:D616) -> 0.56066116 | N7: =COUNT(D7:D616) -> 605 | O7: =SUM(H7:H616) -> 33796 | P7: =AVERAGE(H7:H616) -> 55.861157 | Q7: =COUNT(H7:H616) -> 605 | R7: =LEFT(B7,1) -> 6 | S7: =RIGHT(B7,1) -> 6 | T7: =LEN(B7) -> 1 | U7: =COUNTIF(H:H,">100") -> 89 | V7: =SUMIF(D:D,">0.8",H:H) -> 3183 | W7: =STDEV(H:H) -> 49.316802 | X7: =CORREL(C:C,H:H) -> 0.18825987
A8: 6 | B8: 7 | C8: 0.2727 | D8: 0.8 | E8: 0 | F8: 2 | G8: 0 | H8: 2 | I8: =SUM(C8:C617) -> 120.29359 | J8: =AVERAGE(C8:C617) -> 0.19916156 | K8: =COUNT(C8:C617) -> 604 | L8: =SUM(D8:D617) -> 338.45 | M8: =AVERAGE(D8:D617) -> 0.56034768 | N8: =COUNT(D8:D617) -> 604 | O8: =SUM(H8:H617) -> 33795 | P8: =AVERAGE(H8:H617) -> 55.951987 | Q8: =COUNT(H8:H617) -> 604 | R8: =LEFT(B8,1) -> 7 | S8: =RIGHT(B8,1) -> 7 | T8: =LEN(B8) -> 1 | U8: =COUNTIF(H:H,">100") -> 89 | V8: =SUMIF(D:D,">0.8",H:H) -> 3183 | W8: =STDEV(H:H) -> 49.316802 | X8: =CORREL(C:C,H:H) -> 0.18825987
A9: 7 | B9: 8 | C9: 0.2576 | D9: 0.86 | E9: 0 | F9: 1 | G9: 2 | H9: 3 | I9: =SUM(C9:C618) -> 120.02089 | J9: =AVERAGE(C9:C618) -> 0.19903961 | K9: =COUNT(C9:C618) -> 603 | L9: =SUM(D9:D618) -> 337.65 | M9: =AVERAGE(D9:D618) -> 0.55995025 | N9: =COUNT(D9:D618) -> 603 | O9: =SUM(H9:H618) -> 33793 | P9: =AVERAGE(H9:H618) -> 56.041459 | Q9: =COUNT(H9:H618) -> 603 | R9: =LEFT(B9,1) -> 8 | S9: =RIGHT(B9,1) -> 8 | T9: =LEN(B9) -> 1 | U9: =COUNTIF(H:H,">100") -> 89 | V9: =SUMIF(D:D,">0.8",H:H) -> 3183 | W9: =STDEV(H:H) -> 49.316802 | X9: =CORREL(C:C,H:H) -> 0.18825987
A10: 8 | B10: 9 | C10: 0.199935 | D10: 0.75 | E10: 0 | F10: 1 | G10: 7 | H10: 8 | I10: =SUM(C10:C619) -> 119.76329 | J10: =AVERAGE(C10:C619) -> 0.19894233 | K10: =COUNT(C10:C619) -> 602 | L10: =SUM(D10:D619) -> 336.79 | M10: =AVERAGE(D10:D619) -> 0.55945183 | N10: =COUNT(D10:D619) -> 602 | O10: =SUM(H10:H619) -> 33790 | P10: =AVERAGE(H10:H619) -> 56.129568 | Q10: =COUNT(H10:H619) -> 602 | R10: =LEFT(B10,1) -> 9 | S10: =RIGHT(B10,1) -> 9 | T10: =LEN(B10) -> 1 | U10: =COUNTIF(H:H,">100") -> 89 | V10: =SUMIF(D:D,">0.8",H:H) -> 3183 | W10: =STDEV(H:H) -> 49.316802 | X10: =CORREL(C:C,H:H) -> 0.18825987
A11: 9 | B11: 10 | C11: 0.3485 | D11: 0.76 | E11: 0 | F11: 8 | G11: 6 | H11: 14 | I11: =SUM(C11:C620) -> 119.56335 | J11: =AVERAGE(C11:C620) -> 0.19894068 | K11: =COUNT(C11:C620) -> 601 | L11: =SUM(D11:D620) -> 336.04 | M11: =AVERAGE(D11:D620) -> 0.55913478 | N11: =COUNT(D11:D620) -> 601 | O11: =SUM(H11:H620) -> 33782 | P11: =AVERAGE(H11:H620) -> 56.209651 | Q11: =COUNT(H11:H620) -> 601 | R11: =LEFT(B11,1) -> 1 | S11: =RIGHT(B11,1) -> 0 | T11: =LEN(B11) -> 2 | U11: =COUNTIF(H:H,">100") -> 89 | V11: =SUMIF(D:D,">0.8",H:H) -> 3183 | W11: =STDEV(H:H) -> 49.316802 | X11: =CORREL(C:C,H:H) -> 0.18825987
A12: 10 | B12: 11 | C12: 0.3939 | D12: 0.76 | E12: 0.2537 | F12: 12 | G12: 24 | H12: 36 | I12: =SUM(C12:C621) -> 119.21485 | J12: =AVERAGE(C12:C621) -> 0.19869142 | K12: =COUNT(C12:C621) -> 600 | L12: =SUM(D12:D621) -> 335.28 | M12: =AVERAGE(D12:D621) -> 0.5588 | N12: =COUNT(D12:D621) -> 600 | O12: =SUM(H12:H621) -> 33768 | P12: =AVERAGE(H12:H621) -> 56.28 | Q12: =COUNT(H12:H621) -> 600 | R12: =LEFT(B12,1) -> 1 | S12: =RIGHT(B12,1) -> 1 | T12: =LEN(B12) -> 2 | U12: =COUNTIF(H:H,">100") -> 89 | V12: =SUMIF(D:D,">0.8",H:H) -> 3183 | W12: =STDEV(H:H) -> 49.316802 | X12: =CORREL(C:C,H:H) -> 0.18825987
A13: 11 | B13: 12 | C13: 0.3333 | D13: 0.81 | E13: 0.2836 | F13: 26 | G13: 30 | H13: 56 | I13: =SUM(C13:C622) -> 118.82095 | J13: =AVERAGE(C13:C622) -> 0.19836553 | K13: =COUNT(C13:C622) -> 599 | L13: =SUM(D13:D622) -> 334.52 | M13: =AVERAGE(D13:D622) -> 0.55846411 | N13: =COUNT(D13:D622) -> 599 | O13: =SUM(H13:H622) -> 33732 | P13: =AVERAGE(H13:H622) -> 56.313856 | Q13: =COUNT(H13:H622) -> 599 | R13: =LEFT(B13,1) -> 1 | S13: =RIGHT(B13,1) -> 2 | T13: =LEN(B13) -> 2 | U13: =COUNTIF(H:H,">100") -> 89 | V13: =SUMIF(D:D,">0.8",H:H) -> 3183 | W13: =STDEV(H:H) -> 49.316802 | X13: =CORREL(C:C,H:H) -> 0.18825987
... A611: 609 | B611: 610 | C611: 0.2576 | D611: 0.86 | E611: 0 | F611: 1 | G611: 40 | H611: 41 | I611: =SUM(C611:C1220) -> 0.2576 | J611: =AVERAGE(C611:C1220) -> 0.2576 | K611: =COUNT(C611:C1220) -> 1 | L611: =SUM(D611:D1220) -> 0.86 | M611: =AVERAGE(D611:D1220) -> 0.86 | N611: =COUNT(D611:D1220) -> 1 | O611: =SUM(H611:H1220) -> 41 | P611: =AVERAGE(H611:H1220) -> 41 | Q611: =COUNT(H611:H1220) -> 1 | R611: =LEFT(B611,1) -> 6 | S611: =RIGHT(B611,1) -> 0 | T611: =LEN(B611) -> 3 | U611: =COUNTIF(H:H,">100") -> 89 | V611: =SUMIF(D:D,">0.8",H:H) -> 3183 | W611: =STDEV(H:H) -> 49.316802 | X611: =CORREL(C:C,H:H) -> 0.18825987

Sheet Sheet2
A1: Unnamed: 0 | B1: instant | C1: atemp | D1: hum | E1: windspeed | F1: casual | G1: registered | H1: cnt | I1: Total atemp | J1: Avg atemp | K1: count atemp | L1: total hum | M1: Avg hum | N1: count hum | O1: total cnt | P1: Avg cnt | Q1: count cnt | R1: left instant | S1: right instant | T1: lenght instant | U1: Status
A2: 0 | B2: 1 | C2: 0.2879 | D2: 0.81 | E2: 0 | F2: 3 | G2: 13 | H2: 16 | I2: =SUM(C2:C611) -> 119.761 | J2: =AVERAGE(C2:C611) -> 0.19993489 | K2: =COUNT(C2:C611) -> 599 | L2: =SUM(D2:D611) -> 343.11 | M2: =AVERAGE(D2:D611) -> 0.56247541 | N2: =COUNT(D2:D611) -> 610 | O2: =SUM(H2:H611) -> 33898 | P2: =AVERAGE(H2:H611) -> 55.570492 | Q2: =COUNT(H2:H611) -> 610 | R2: =LEFT(B2,1) -> 1 | S2: =RIGHT(B2,1) -> 1 | T2: =LEN(B2) -> 1 | U2: =IF(R2=S2,"Match","Mismatch") -> Match
A3: 1 | B3: 2 | C3: 0.2727 | D3: 0.8 | E3: 0 | F3: 8 | G3: 32 | H3: 40 | I3: =SUM(C3:C612) -> 119.4731 | J3: =AVERAGE(C3:C612) -> 0.19978779 | K3: =COUNT(C3:C612) -> 598 | L3: =SUM(D3:D612) -> 342.3 | M3: =AVERAGE(D3:D612) -> 0.56206897 | N3: =COUNT(D3:D612) -> 609 | O3: =SUM(H3:H612) -> 33882 | P3: =AVERAGE(H3:H612) -> 55.635468 | Q3: =COUNT(H3:H612) -> 609 | R3: =LEFT(B3,1) -> 2 | S3: =RIGHT(B3,1) -> 2 | T3: =LEN(B3) -> 1 | U3: =IF(R3=S3,"Match","Mismatch") -> Match
A4: 2 | B4: 3 | C4: 0.2727 | D4: 0.8 | E4: 0 | F4: 5 | G4: 27 | H4: 32 | I4: =SUM(C4:C613) -> 119.2004 | J4: =AVERAGE(C4:C613) -> 0.19966566 | K4: =COUNT(C4:C613) -> 597 | L4: =SUM(D4:D613) -> 341.5 | M4: =AVERAGE(D4:D613) -> 0.56167763 | N4: =COUNT(D4:D613) -> 608 | O4: =SUM(H4:H613) -> 33842 | P4: =AVERAGE(H4:H613) -> 55.661184 | Q4: =COUNT(H4:H613) -> 608 | R4: =LEFT(B4,1) -> 3 | S4: =RIGHT(B4,1) -> 3 | T4: =LEN(B4) -> 1 | U4: =IF(R4=S4,"Match","Mismatch") -> Match
A5: 3 | B5: 4 | C5: 0.2879 | D5: 0.75 | E5: 0 | F5: 3 | G5: 10 | H5: 13 | I5: =SUM(C5:C614) -> 118.9277 | J5: =AVERAGE(C5:C614) -> 0.19954312 | K5: =COUNT(C5:C614) -> 596 | L5: =SUM(D5:D614) -> 340.7 | M5: =AVERAGE(D5:D614) -> 0.56128501 | N5: =COUNT(D5:D614) -> 607 | O5: =SUM(H5:H614) -> 33810 | P5: =AVERAGE(H5:H614) -> 55.700165 | Q5: =COUNT(H5:H614) -> 607 | R5: =LEFT(B5,1) -> 4 | S5: =RIGHT(B5,1) -> 4 | T5: =LEN(B5) -> 1 | U5: =IF(R5=S5,"Match","Mismatch") -> Match
A6: 4 | B6: 5 | C6: 0.2879 | D6: 0.75 | E6: 0 | F6: 0 | G6: 1 | H6: 1 | I6: =SUM(C6:C615) -> 118.6398 | J6: =AVERAGE(C6:C615) -> 0.19939462 | K6: =COUNT(C6:C615) -> 595 | L6: =SUM(D6:D615) -> 339.95 | M6: =AVERAGE(D6:D615) -> 0.5609736 | N6: =COUNT(D6:D615) -> 606 | O6: =SUM(H6:H615) -> 33797 | P6: =AVERAGE(H6:H615) -> 55.770627 | Q6: =COUNT(H6:H615) -> 606 | R6: =LEFT(B6,1) -> 5 | S6: =RIGHT(B6,1) -> 5 | T6: =LEN(B6) -> 1 | U6: =IF(R6=S6,"Match","Mismatch") -> Match
A7: 5 | B7: 6 | C7: 0.2576 | D7: 0.75 | E7: 0.0896 | F7: 0 | G7: 1 | H7: 1 | I7: =SUM(C7:C616) -> 118.3519 | J7: =AVERAGE(C7:C616) -> 0.19924562 | K7: =COUNT(C7:C616) -> 594 | L7: =SUM(D7:D616) -> 339.2 | M7: =AVERAGE(D7:D616) -> 0.56066116 | N7: =COUNT(D7:D616) -> 605 | O7: =SUM(H7:H616) -> 33796 | P7: =AVERAGE(H7:H616) -> 55.861157 | Q7: =COUNT(H7:H616) -> 605 | R7: =LEFT(B7,1) -> 6 | S7: =RIGHT(B7,1) -> 6 | T7: =LEN(B7) -> 1 | U7: =IF(R7=S7,"Match","Mismatch") -> Match
A8: 6 | B8: 7 | C8: 0.2727 | D8: 0.8 | E8: 0 | F8: 2 | G8: 0 | H8: 2 | I8: =SUM(C8:C617) -> 118.0943 | J8: =AVERAGE(C8:C617) -> 0.19914722 | K8: =COUNT(C8:C617) -> 593 | L8: =SUM(D8:D617) -> 338.45 | M8: =AVERAGE(D8:D617) -> 0.56034768 | N8: =COUNT(D8:D617) -> 604 | O8: =SUM(H8:H617) -> 33795 | P8: =AVERAGE(H8:H617) -> 55.951987 | Q8: =COUNT(H8:H617) -> 604 | R8: =LEFT(B8,1) -> 7 | S8: =RIGHT(B8,1) -> 7 | T8: =LEN(B8) -> 1 | U8: =IF(R8=S8,"Match","Mismatch") -> Match
A9: 7 | B9: 8 | C9: 0.2576 | D9: 0.86 | E9: 0 | F9: 1 | G9: 2 | H9: 3 | I9: =SUM(C9:C618) -> 117.8216 | J9: =AVERAGE(C9:C618) -> 0.19902297 | K9: =COUNT(C9:C618) -> 592 | L9: =SUM(D9:D618) -> 337.65 | M9: =AVERAGE(D9:D618) -> 0.55995025 | N9: =COUNT(D9:D618) -> 603 | O9: =SUM(H9:H618) -> 33793 | P9: =AVERAGE(H9:H618) -> 56.041459 | Q9: =COUNT(H9:H618) -> 603 | R9: =LEFT(B9,1) -> 8 | S9: =RIGHT(B9,1) -> 8 | T9: =LEN(B9) -> 1 | U9: =IF(R9=S9,"Match","Mismatch") -> Match
A10: 8 | B10: 9 | D10: 0.75 | E10: 0 | F10: 1 | G10: 7 | H10: 8 | I10: =SUM(C10:C619) -> 117.564 | J10: =AVERAGE(C10:C619) -> 0.19892386 | K10: =COUNT(C10:C619) -> 591 | L10: =SUM(D10:D619) -> 336.79 | M10: =AVERAGE(D10:D619) -> 0.55945183 | N10: =COUNT(D10:D619) -> 602 | O10: =SUM(H10:H619) -> 33790 | P10: =AVERAGE(H10:H619) -> 56.129568 | Q10: =COUNT(H10:H619) -> 602 | R10: =LEFT(B10,1) -> 9 | S10: =RIGHT(B10,1) -> 9 | T10: =LEN(B10) -> 1 | U10: =IF(R10=S10,"Match","Mismatch") -> Match
A11: 9 | B11: 10 | C11: 0.3485 | D11: 0.76 | E11: 0 | F11: 8 | G11: 6 | H11: 14 | I11: =SUM(C11:C620) -> 117.564 | J11: =AVERAGE(C11:C620) -> 0.19892386 | K11: =COUNT(C11:C620) -> 591 | L11: =SUM(D11:D620) -> 336.04 | M11: =AVERAGE(D11:D620) -> 0.55913478 | N11: =COUNT(D11:D620) -> 601 | O11: =SUM(H11:H620) -> 33782 | P11: =AVERAGE(H11:H620) -> 56.209651 | Q11: =COUNT(H11:H620) -> 601 | R11: =LEFT(B11,1) -> 1 | S11: =RIGHT(B11,1) -> 0 | T11: =LEN(B11) -> 2 | U11: =IF(R11=S11,"Match","Mismatch") -> Mismatch
A12: 10 | B12: 11 | C12: 0.3939 | D12: 0.76 | E12: 0.2537 | F12: 12 | G12: 24 | H12: 36 | I12: =SUM(C12:C621) -> 117.2155 | J12: =AVERAGE(C12:C621) -> 0.19867034 | K12: =COUNT(C12:C621) -> 590 | L12: =SUM(D12:D621) -> 335.28 | M12: =AVERAGE(D12:D621) -> 0.5588 | N12: =COUNT(D12:D621) -> 600 | O12: =SUM(H12:H621) -> 33768 | P12: =AVERAGE(H12:H621) -> 56.28 | Q12: =COUNT(H12:H621) -> 600 | R12: =LEFT(B12,1) -> 1 | S12: =RIGHT(B12,1) -> 1 | T12: =LEN(B12) -> 2 | U12: =IF(R12=S12,"Match","Mismatch") -> Match
A13: 11 | B13: 12 | C13: 0.3333 | D13: 0.81 | E13: 0.2836 | F13: 26 | G13: 30 | H13: 56 | I13: =SUM(C13:C622) -> 116.8216 | J13: =AVERAGE(C13:C622) -> 0.19833888 | K13: =COUNT(C13:C622) -> 589 | L13: =SUM(D13:D622) -> 334.52 | M13: =AVERAGE(D13:D622) -> 0.55846411 | N13: =COUNT(D13:D622) -> 599 | O13: =SUM(H13:H622) -> 33732 | P13: =AVERAGE(H13:H622) -> 56.313856 | Q13: =COUNT(H13:H622) -> 599 | R13: =LEFT(B13,1) -> 1 | S13: =RIGHT(B13,1) -> 2 | T13: =LEN(B13) -> 2 | U13: =IF(R13=S13,"Match","Mismatch") -> Mismatch
A14: 12 | B14: 13 | C14: 0.4242 | D14: 0.77 | E14: 0.2836 | F14: 29 | G14: 55 | H14: 84 | I14: =SUM(C14:C623) -> 116.4883 | J14: =AVERAGE(C14:C623) -> 0.19810935 | K14: =COUNT(C14:C623) -> 588 | L14: =SUM(D14:D623) -> 333.71 | M14: =AVERAGE(D14:D623) -> 0.55804348 | N14: =COUNT(D14:D623) -> 598 | O14: =SUM(H14:H623) -> 33676 | P14: =AVERAGE(H14:H623) -> 56.314381 | Q14: =COUNT(H14:H623) -> 598 | R14: =LEFT(B14,1) -> 1 | S14: =RIGHT(B14,1) -> 3 | T14: =LEN(B14) -> 2 | U14: =IF(R14=S14,"Match","Mismatch") -> Mismatch
A15: 13 | B15: 14 | C15: 0.4545 | D15: 0.72 | E15: 0.2985 | F15: 47 | G15: 47 | H15: 94 | I15: =SUM(C15:C624) -> 116.0641 | J15: =AVERAGE(C15:C624) -> 0.19772419 | K15: =COUNT(C15:C624) -> 587 | L15: =SUM(D15:D624) -> 332.94 | M15: =AVERAGE(D15:D624) -> 0.55768844 | N15: =COUNT(D15:D624) -> 597 | O15: =SUM(H15:H624) -> 33592 | P15: =AVERAGE(H15:H624) -> 56.268007 | Q15: =COUNT(H15:H624) -> 597 | R15: =LEFT(B15,1) -> 1 | S15: =RIGHT(B15,1) -> 4 | T15: =LEN(B15) -> 2 | U15: =IF(R15=S15,"Match","Mismatch") -> Mismatch
A16: 14 | B16: 15 | C16: 0.4545 | D16: 0.72 | E16: 0.2836 | F16: 35 | G16: 71 | H16: 106 | I16: =SUM(C16:C625) -> 115.6096 | J16: =AVERAGE(C16:C625) -> 0.19728601 | K16: =COUNT(C16:C625) -> 586 | L16: =SUM(D16:D625) -> 332.22 | M16: =AVERAGE(D16:D625) -> 0.55741611 | N16: =COUNT(D16:D625) -> 596 | O16: =SUM(H16:H625) -> 33498 | P16: =AVERAGE(H16:H625) -> 56.204698 | Q16: =COUNT(H16:H625) -> 596 | R16: =LEFT(B16,1) -> 1 | S16: =RIGHT(B16,1) -> 5 | T16: =LEN(B16) -> 2 | U16: =IF(R16=S16,"Match","Mismatch") -> Mismatch
A17: 15 | B17: 16 | C17: 0.4394 | D17: 0.77 | E17: 0.2985 | F17: 40 | G17: 70 | H17: 110 | I17: =SUM(C17:C626) -> 115.1551 | J17: =AVERAGE(C17:C626) -> 0.19684632 | K17: =COUNT(C17:C626) -> 585 | L17: =SUM(D17:D626) -> 331.5 | M17: =AVERAGE(D17:D626) -> 0.55714286 | N17: =COUNT(D17:D626) -> 595 | O17: =SUM(H17:H626) -> 33392 | P17: =AVERAGE(H17:H626) -> 56.121008 | Q17: =COUNT(H17:H626) -> 595 | R17: =LEFT(B17,1) -> 1 | S17: =RIGHT(B17,1) -> 6 | T17: =LEN(B17) -> 2 | U17: =IF(R17=S17,"Match","Mismatch") -> Mismatch
A18: 16 | B18: 17 | C18: 0.4242 | D18: 0.82 | E18: 0.2985 | F18: 41 | G18: 52 | H18: 93 | I18: =SUM(C18:C627) -> 114.7157 | J18: =AVERAGE(C18:C627) -> 0.19643099 | K18: =COUNT(C18:C627) -> 584 | L18: =SUM(D18:D627) -> 330.73 | M18: =AVERAGE(D18:D627) -> 0.55678451 | N18: =COUNT(D18:D627) -> 594 | O18: =SUM(H18:H627) -> 33282 | P18: =AVERAGE(H18:H627) -> 56.030303 | Q18: =COUNT(H18:H627) -> 594 | R18: =LEFT(B18,1) -> 1 | S18: =RIGHT(B18,1) -> 7 | T18: =LEN(B18) -> 2 | U18: =IF(R18=S18,"Match","Mismatch") -> Mismatch
A19: 17 | B19: 18 | D19: 0.82 | E19: 0.2836 | F19: 15 | G19: 52 | H19: 67 | I19: =SUM(C19:C628) -> 114.2915 | J19: =AVERAGE(C19:C628) -> 0.19604031 | K19: =COUNT(C19:C628) -> 583 | L19: =SUM(D19:D628) -> 329.91 | M19: =AVERAGE(D19:D628) -> 0.55634064 | N19: =COUNT(D19:D628) -> 593 | O19: =SUM(H19:H628) -> 33189 | P19: =AVERAGE(H19:H628) -> 55.96796 | Q19: =COUNT(H19:H628) -> 593 | R19: =LEFT(B19,1) -> 1 | S19: =RIGHT(B19,1) -> 8 | T19: =LEN(B19) -> 2 | U19: =IF(R19=S19,"Match","Mismatch") -> Mismatch
A20: 18 | B20: 19 | C20: 0.4242 | D20: 0.88 | E20: 0.2537 | F20: 9 | G20: 26 | H20: 35 | I20: =SUM(C20:C629) -> 114.2915 | J20: =AVERAGE(C20:C629) -> 0.19604031 | K20: =COUNT(C20:C629) -> 583 | L20: =SUM(D20:D629) -> 329.09 | M20: =AVERAGE(D20:D629) -> 0.55589527 | N20: =COUNT(D20:D629) -> 592 | O20: =SUM(H20:H629) -> 33122 | P20: =AVERAGE(H20:H629) -> 55.949324 | Q20: =COUNT(H20:H629) -> 592 | R20: =LEFT(B20,1) -> 1 | S20: =RIGHT(B20,1) -> 9 | T20: =LEN(B20) -> 2 | U20: =IF(R20=S20,"Match","Mismatch") -> Mismatch
A21: 19 | B21: 20 | C21: 0.4242 | D21: 0.88 | E21: 0.2537 | F21: 6 | G21: 31 | H21: 37 | I21: =SUM(C21:C630) -> 113.8673 | J21: =AVERAGE(C21:C630) -> 0.19564828 | K21: =COUNT(C21:C630) -> 582 | L21: =SUM(D21:D630) -> 328.21 | M21: =AVERAGE(D21:D630) -> 0.55534687 | N21: =COUNT(D21:D630) -> 591 | O21: =SUM(H21:H630) -> 33087 | P21: =AVERAGE(H21:H630) -> 55.984772 | Q21: =COUNT(H21:H630) -> 591 | R21: =LEFT(B21,1) -> 2 | S21: =RIGHT(B21,1) -> 0 | T21: =LEN(B21) -> 2 | U21: =IF(R21=S21,"Match","Mismatch") -> Mismatch
A22: 20 | B22: 21 | C22: 0.4091 | D22: 0.87 | E22: 0.2537 | F22: 11 | G22: 25 | H22: 36 | I22: =SUM(C22:C631) -> 113.4431 | J22: =AVERAGE(C22:C631) -> 0.19525491 | K22: =COUNT(C22:C631) -> 581 | L22: =SUM(D22:D631) -> 327.33 | M22: =AVERAGE(D22:D631) -> 0.55479661 | N22: =COUNT(D22:D631) -> 590 | O22: =SUM(H22:H631) -> 33050 | P22: =AVERAGE(H22:H631) -> 56.016949 | Q22: =COUNT(H22:H631) -> 590 | R22: =LEFT(B22,1) -> 2 | S22: =RIGHT(B22,1) -> 1 | T22: =LEN(B22) -> 2 | U22: =IF(R22=S22,"Match","Mismatch") -> Mismatch
A23: 21 | B23: 22 | C23: 0.4091 | D23: 0.87 | E23: 0.194 | F23: 3 | G23: 31 | H23: 34 | I23: =SUM(C23:C632) -> 113.034 | J23: =AVERAGE(C23:C632) -> 0.19488621 | K23: =COUNT(C23:C632) -> 580 | L23: =SUM(D23:D632) -> 326.46 | M23: =AVERAGE(D23:D632) -> 0.55426146 | N23: =COUNT(D23:D632) -> 589 | O23: =SUM(H23:H632) -> 33014 | P23: =AVERAGE(H23:H632) -> 56.050934 | Q23: =COUNT(H23:H632) -> 589 | R23: =LEFT(B23,1) -> 2 | S23: =RIGHT(B23,1) -> 2 | T23: =LEN(B23) -> 2 | U23: =IF(R23=S23,"Match","Mismatch") -> Match
A24: 22 | B24: 23 | C24: 0.4091 | D24: 0.94 | E24: 0.2239 | F24: 11 | G24: 17 | H24: 28 | I24: =SUM(C24:C633) -> 112.6249 | J24: =AVERAGE(C24:C633) -> 0.19451623 | K24: =COUNT(C24:C633) -> 579 | L24: =SUM(D24:D633) -> 325.59 | M24: =AVERAGE(D24:D633) -> 0.55372449 | N24: =COUNT(D24:D633) -> 588 | O24: =SUM(H24:H633) -> 32980 | P24: =AVERAGE(H24:H633) -> 56.088435 | Q24: =COUNT(H24:H633) -> 588 | R24: =LEFT(B24,1) -> 2 | S24: =RIGHT(B24,1) -> 3 | T24: =LEN(B24) -> 2 | U24: =IF(R24=S24,"Match","Mismatch") -> Mismatch
A25: 23 | B25: 24 | D25: 0.88 | E25: 0.2985 | F25: 15 | G25: 24 | H25: 39 | I25: =SUM(C25:C634) -> 112.2158 | J25: =AVERAGE(C25:C634) -> 0.19414498 | K25: =COUNT(C25:C634) -> 578 | L25: =SUM(D25:D634) -> 324.65 | M25: =AVERAGE(D25:D634) -> 0.55306644 | N25: =COUNT(D25:D634) -> 587 | O25: =SUM(H25:H634) -> 32952 | P25: =AVERAGE(H25:H634) -> 56.136286 | Q25: =COUNT(H25:H634) -> 587 | R25: =LEFT(B25,1) -> 2 | S25: =RIGHT(B25,1) -> 4 | T25: =LEN(B25) -> 2 | U25: =IF(R25=S25,"Match","Mismatch") -> Mismatch
A26: 24 | B26: 25 | C26: 0.4545 | D26: 0.88 | E26: 0.2985 | F26: 4 | G26: 13 | H26: 17 | I26: =SUM(C26:C635) -> 112.2158 | J26: =AVERAGE(C26:C635) -> 0.19414498 | K26: =COUNT(C26:C635) -> 578 | L26: =SUM(D26:D635) -> 323.77 | M26: =AVERAGE(D26:D635) -> 0.55250853 | N26: =COUNT(D26:D635) -> 586 | O26: =SUM(H26:H635) -> 32913 | P26: =AVERAGE(H26:H635) -> 56.165529 | Q26: =COUNT(H26:H635) -> 586 | R26: =LEFT(B26,1) -> 2 | S26: =RIGHT(B26,1) -> 5 | T26: =LEN(B26) -> 2 | U26: =IF(R26=S26,"Match","Mismatch") -> Mismatch
A27: 25 | B27: 26 | C27: 0.4394 | D27: 0.94 | E27: 0.2537 | F27: 1 | G27: 16 | H27: 17 | I27: =SUM(C27:C636) -> 111.7613 | J27: =AVERAGE(C27:C636) -> 0.19369376 | K27: =COUNT(C27:C636) -> 577 | L27: =SUM(D27:D636) -> 322.89 | M27: =AVERAGE(D27:D636) -> 0.55194872 | N27: =COUNT(D27:D636) -> 585 | O27: =SUM(H27:H636) -> 32896 | P27: =AVERAGE(H27:H636) -> 56.232479 | Q27: =COUNT(H27:H636) -> 585 | R27: =LEFT(B27,1) -> 2 | S27: =RIGHT(B27,1) -> 6 | T27: =LEN(B27) -> 2 | U27: =IF(R27=S27,"Match","Mismatch") -> Mismatch
A28: 26 | B28: 27 | C28: 0.4242 | D28: 1 | E28: 0.2836 | F28: 1 | G28: 8 | H28: 9 | I28: =SUM(C28:C637) -> 111.3219 | J28: =AVERAGE(C28:C637) -> 0.19326719 | K28: =COUNT(C28:C637) -> 576 | L28: =SUM(D28:D637) -> 321.95 | M28: =AVERAGE(D28:D637) -> 0.55128425 | N28: =COUNT(D28:D637) -> 584 | O28: =SUM(H28:H637) -> 32879 | P28: =AVERAGE(H28:H637) -> 56.299658 | Q28: =COUNT(H28:H637) -> 584 | R28: =LEFT(B28,1) -> 2 | S28: =RIGHT(B28,1) -> 7 | T28: =LEN(B28) -> 2 | U28: =IF(R28=S28,"Match","Mismatch") -> Mismatch
A29: 27 | B29: 28 | C29: 0.4545 | D29: 0.94 | E29: 0.194 | F29: 2 | G29: 4 | H29: 6 | I29: =SUM(C29:C638) -> 110.8977 | J29: =AVERAGE(C29:C638) -> 0.19286557 | K29: =COUNT(C29:C638) -> 575 | L29: =SUM(D29:D638) -> 320.95 | M29: =AVERAGE(D29:D638) -> 0.55051458 | N29: =COUNT(D29:D638) -> 583 | O29: =SUM(H29:H638) -> 32870 | P29: =AVERAGE(H29:H638) -> 56.380789 | Q29: =COUNT(H29:H638) -> 583 | R29: =LEFT(B29,1) -> 2 | S29: =RIGHT(B29,1) -> 8 | T29: =LEN(B29) -> 2 | U29: =IF(R29=S29,"Match","Mismatch") -> Mismatch
A30: 28 | B30: 29 | D30: 0.94 | E30: 0.194 | F30: 2 | G30: 1 | H30: 3 | I30: =SUM(C30:C639) -> 110.4432 | J30: =AVERAGE(C30:C639) -> 0.19240976 | K30: =COUNT(C30:C639) -> 574 | L30: =SUM(D30:D639) -> 320.01 | M30: =AVERAGE(D30:D639) -> 0.54984536 | N30: =COUNT(D30:D639) -> 582 | O30: =SUM(H30:H639) -> 32864 | P30: =AVERAGE(H30:H639) -> 56.467354 | Q30: =COUNT(H30:H639) -> 582 | R30: =LEFT(B30,1) -> 2 | S30: =RIGHT(B30,1) -> 9 | T30: =LEN(B30) -> 2 | U30: =IF(R30=S30,"Match","Mismatch") -> Mismatch
